Workbook
Name LCATS: #REF!

Sheet 2025+ Revenue Projections
A1: Year | B1: 2025 | N1: 2026 | Z1: 2027
A2: Month | B2: 1 | C2: 2 | D2: 3 | E2: 4 | F2: 5 | G2: 6 | H2: 7 | I2: 8 | J2: 9 | K2: 10 | L2: 11 | M2: 12 | N2: 1 | O2: 2 | P2: 3 | Q2: 4 | R2: 5 | S2: 6 | T2: 7 | U2: 8 | V2: 9 | W2: 10 | X2: 11 | Y2: 12 | Z2: 1 | AA2: 2 | AB2: 3 | AC2: 4 | AD2: 5 | AE2: 6 | AF2: 7 | AG2: 8 | AH2: 9 | AI2: 10 | AJ2: 11 | AK2: 12
A3: Prime Contracts
A4: AMRIID II | B4: ='AMRIID 2.1'!J140 -> 31889.44 | C4: ='AMRIID 2.1'!K140 -> 31889.44 | D4: ='AMRIID 2.1'!L140 -> 31889.44 | E4: ='AMRIID 2.1'!M140 -> 31889.44 | F4: ='AMRIID 2.1'!N140 -> 31889.44 | G4: ='AMRIID 2.1'!O140 -> 31889.44 | H4: ='AMRIID 2.1'!P140 -> 31889.44 | I4: ='AMRIID 2.1'!Q140 -> 31889.44 | J4: ='AMRIID 2.1'!R140 -> 31889.44
A5: DHS FLETF | B5: ='DHS FLETF'!J109 -> 121462.58 | C5: ='DHS FLETF'!K109 -> 121462.58 | D5: ='DHS FLETF'!L109 -> 121462.58 | E5: ='DHS FLETF'!M109 -> 121462.58 | F5: ='DHS FLETF'!N109 -> 121462.58 | G5: ='DHS FLETF'!O109 -> 121462.58 | H5: ='DHS FLETF'!P109 -> 121462.58
A6: DOT CTS | B6: 33333.33 | C6: 33333.33 | D6: 33333.33 | E6: 33333.33 | F6: 33333.33 | G6: 33333.33 | H6: 33333.33 | I6: 33333.33 | J6: 33333.33
A7: AO Call 1.4 - RAE Support | B7: ='AO Call 1.4'!J116 -> 415263.2 | C7: ='AO Call 1.4'!K116 -> 394609.28
A8: AO Call 2.2 - EA Support | B8: ='AO Call 2.2'!J104 -> 261904 | C8: ='AO Call 2.2'!K104 -> 261904 | D8: ='AO Call 2.2'!L104 -> 261904 | E8: ='AO Call 2.2'!M104 -> 261904 | F8: ='AO Call 2.2'!N104 -> 261904 | G8: ='AO Call 2.2'!O104 -> 246537.6 | H8: ='AO Call 2.2'!P104 -> 264651.2 | I8: ='AO Call 2.2'!Q104 -> 264651.2 | ... V8: ='AO Call 2.2'!AD104 -> 266016.72
A9: AO Call 4.1 - MFA Support | B9: ='AO Call 4.1'!N110 -> 163292.64 | C9: ='AO Call 4.1'!O110 -> 147740.96 | D9: ='AO Call 4.1'!P110 -> 155516.8 | E9: ='AO Call 4.1'!Q110 -> 147740.96 | F9: ='AO Call 4.1'!R110 -> 163292.64 | G9: ='AO Call 4.1'!S110 -> 163292.64 | H9: ='AO Call 4.1'!T110 -> 147740.96 | I9: ='AO Call 4.1'!U110 -> 171068.48 | ... AC9: ='AO Call 4.1'!AO110 -> 147740.96
A10: AO Call 5.1 - Cloud | B10: ='AO Call 5.1'!M110 -> 174456.48 | C10: ='AO Call 5.1'!N110 -> 158596.8 | D10: ='AO Call 5.1'!O110 -> 166526.64 | E10: ='AO Call 5.1'!P110 -> 166526.64
A11: AO Call 6.1 - Cloud DevSecOps | B11: ='AO Call 6.1'!N110 -> 67956.16 | C11: ='AO Call 6.1'!O110 -> 71532.8 | D11: ='AO Call 6.1'!P110 -> 57222.4 | E11: ='AO Call 6.1'!Q110 -> 50064 | F11: ='AO Call 6.1'!R110 -> 50064 | G11: ='AO Call 6.1'!S110 -> 45296 | H11: ='AO Call 6.1'!T110 -> 52448 | I11: ='AO Call 6.1'!U110 -> 42912 | ... R11: ='AO Call 6.1'!AD110 -> 50064
A12: AO Call 8 - GovBoard Support | B12: ='AO Call 8'!Q129 -> 14426.2
A13: AO Call 8.1 - GovBoard Support | C13: ='AO Call 8.1'!F129 -> 11908.8 | D13: ='AO Call 8.1'!G129 -> 11908.8 | E13: ='AO Call 8.1'!H129 -> 11908.8 | F13: ='AO Call 8.1'!I129 -> 11908.8 | G13: ='AO Call 8.1'!J129 -> 11908.8 | H13: ='AO Call 8.1'!K129 -> 11908.8 | I13: ='AO Call 8.1'!L129 -> 11908.8 | J13: ='AO Call 8.1'!M129 -> 11908.8 | ... AK13: ='AO Call 8.1'!AN129 -> 11908.8
A14: AO Call 10 - External File Sharing | B14: ='AO Call 10.1'!I109 -> 39494.4
A15: AO Call 12 - EITPM | B15: ='AO Call 12'!J179 -> 123431.18 | C15: ='AO Call 12'!K179 -> 11667.48 | D15: ='AO Call 12'!L179 -> 170372.28 | E15: ='AO Call 12'!M179 -> 109435.36 | F15: ='AO Call 12'!N179 -> 125167.68 | G15: ='AO Call 12'!O179 -> 102409.92 | H15: ='AO Call 12'!P179 -> 125167.68
A16: AO Call 13 - DevSecOps | B16: ='AO Call 13'!J110 -> 92120 | C16: ='AO Call 13'!K110 -> 87514 | D16: ='AO Call 13'!L110 -> 92120 | E16: ='AO Call 13'!M110 -> 96726 | F16: ='AO Call 13'!N110 -> 128066.4 | G16: ='AO Call 13'!O110 -> 148528.8 | H16: ='AO Call 13'!P110 -> 181535.2 | I16: ='AO Call 13'!Q110 -> 173283.6 | ... AK16: ='AO Call 13'!AS110 -> 110602.8
A17: AO Call 14 - ICAM | B17: ='AO Call 14'!J169 -> 162360.8 | C17: ='AO Call 14'!K169 -> 271172.36 | D17: ='AO Call 14'!L169 -> 16860.9 | E17: ='AO Call 14'!M169 -> 16860.9 | F17: ='AO Call 14'!N169 -> 32634 | G17: ='AO Call 14'!O169 -> 40792.5 | H17: ='AO Call 14'!P169 -> 40792.5
A18: AO Call 15 - R&I | B18: ='AO Call 15'!J110 -> 152105.6 | C18: ='AO Call 15'!K110 -> 139025.28 | D18: ='AO Call 15'!L110 -> 146342.4 | E18: ='AO Call 15'!M110 -> 173827.92 | F18: ='AO Call 15'!N110 -> 182105.44 | G18: ='AO Call 15'!O110 -> 148010.4 | H18: ='AO Call 15'!P110 -> 180901.6 | I18: ='AO Call 15'!Q110 -> 172678.8 | ... AH18: ='AO Call 15'!AP110 -> 129289.76
A20: USCIS RIVER | F20: 574793.48 | G20: 574793.48 | H20: 574793.48 | I20: 574793.48 | J20: 574793.48 | K20: 574793.48 | L20: 574793.48 | M20: 574793.48 | N20: 574793.48 | O20: 574793.48 | P20: 574793.48 | Q20: 574793.48 | R20: 589152.68 | S20: 589152.68 | T20: 589152.68 | U20: 589152.68 | V20: 589152.68 | W20: 589152.68 | X20: 589152.68 | Y20: 589152.68 | Z20: 589152.68 | AA20: 589152.68 | AB20: 589152.68 | AC20: 589152.68 | AD20: 603882.48 | AE20: 603882.48 | AF20: 603882.48 | AG20: 603882.48 | AH20: 603882.48 | AI20: 603882.48 | AJ20: 603882.48 | AK20: 603882.48
A22: Subcontracts
A23: IAE | B23: =IAE!E76 -> 91915 | C23: =IAE!F76 -> 91915 | D23: =IAE!G76 -> 91915 | E23: =IAE!H76 -> 91915 | F23: =IAE!I76 -> 91915 | G23: =IAE!J76 -> 91915 | H23: =IAE!K76 -> 91915 | I23: =IAE!L76 -> 91915 | J23: =IAE!M76 -> 91915
A24: ODOS III | B24: =ODOS!E91 -> 233670.4 | C24: =ODOS!F91 -> 0 | D24: =ODOS!G91 -> 0 | E24: =ODOS!H91 -> 0 | F24: =ODOS!I91 -> 0 | G24: =ODOS!J91 -> 0 | H24: =ODOS!K91 -> 0
A25: FDA CAEMS | B25: 14496 | C25: 14496 | D25: 17504.73 | E25: 14496 | F25: 14496 | G25: 17504.73 | H25: 14496 | I25: 14496 | J25: 17504.73 | K25: 14496 | L25: 14496 | M25: 17504.73
A26: FEMA | B26: =FEMA!E91 -> 70160 | C26: =FEMA!F91 -> 63144 | D26: =FEMA!G91 -> 70160 | E26: =FEMA!H91 -> 73668 | F26: =FEMA!I91 -> 70160 | G26: =FEMA!J91 -> 66652
A27: DHS - Entity List | B27: 121462.58 | C27: 121462.58 | D27: 121462.58 | E27: 121462.58 | F27: 121462.58 | G27: 121462.58 | H27: 121462.58 | I27: 121462.58 | J27: 121462.58 | K27: 124907.22 | L27: 124907.22 | M27: 124907.22 | N27: 124907.22 | O27: 124907.22 | P27: 124907.22 | Q27: 124907.22 | R27: 124907.22 | S27: 124907.22 | T27: 124907.22 | U27: 124907.22 | V27: 124907.22 | W27: 128607.05 | X27: 128607.05 | Y27: 128607.05 | Z27: 128607.05 | AA27: 128607.05 | AB27: 128607.05 | AC27: 128607.05 | AD27: 128607.05 | AE27: 128607.05 | AF27: 128607.05 | AG27: 128607.05 | AH27: 128607.05
A28: GAO TIS | H28: =95*160*30 -> 456000 | I28: =95*160*30 -> 456000 | J28: =95*160*30 -> 456000 | K28: =95*160*30 -> 456000 | L28: =95*160*30 -> 456000 | M28: =95*160*30 -> 456000 | N28: =95*160*30 -> 456000 | O28: =95*160*30 -> 456000 | ... S28: =95*160*30 -> 456000 | T28: =97.38*160*30 -> 467424 | U28: =97.38*160*30 -> 467424 | V28: =97.38*160*30 -> 467424 | W28: =97.38*160*30 -> 467424 | X28: =97.38*160*30 -> 467424 | Y28: =97.38*160*30 -> 467424 | Z28: =97.38*160*30 -> 467424 | AA28: =97.38*160*30 -> 467424 | ... AE28: =97.38*160*30 -> 467424 | AF28: =99.81*160*30 -> 479088 | AG28: =99.81*160*30 -> 479088 | AH28: =99.81*160*30 -> 479088 | AI28: =99.81*160*30 -> 479088 | AJ28: =99.81*160*30 -> 479088 | AK28: =99.81*160*30 -> 479088
A30: Summary - All Projects
A31: Year | B31: 2025 | N31: 2026 | Z31: 2027
A32: Month | B32: 1 | C32: 2 | D32: 3 | E32: 4 | F32: 5 | G32: 6 | H32: 7 | I32: 8 | J32: 9 | K32: 10 | L32: 11 | M32: 12 | N32: 1 | O32: 2 | P32: 3 | Q32: 4 | R32: 5 | S32: 6 | T32: 7 | U32: 8 | V32: 9 | W32: 10 | X32: 11 | Y32: 12 | Z32: 1 | AA32: 2 | AB32: 3 | AC32: 4 | AD32: 5 | AE32: 6 | AF32: 7 | AG32: 8 | AH32: 9 | AI32: 10 | AJ32: 11 | AK32: 12
A33: Forecast Rev | B33: =SUM(B4:B22)+SUM(B23:B29) -> 2385200 | C33: =SUM(C4:C22)+SUM(C23:C29) -> 2033374.7 | D33: =SUM(D4:D22)+SUM(D23:D29) -> 1566501.9 | E33: =SUM(E4:E22)+SUM(E23:E29) -> 1523221.5 | F33: =SUM(F4:F22)+SUM(F23:F29) -> 2014655.4 | G33: =SUM(G4:G22)+SUM(G23:G29) -> 1965789.8 | H33: =SUM(H4:H22)+SUM(H23:H29) -> 2450498.4 | I33: =SUM(I4:I22)+SUM(I23:I29) -> 2160392.7 | ... AK33: =SUM(AK4:AK22)+SUM(AK23:AK29) -> 1205482.1
K35: 2025 Year End Summary
B36: Total Backlog: | C36: =SUM(B33:AK33) -> 63741788 | L36: Prime Contract Rev | M36: =SUM(B4:M21) -> 18249303
L37: SubK Rev | M37: =SUM(B23:M29) -> 5864721.2
M38: =SUM(M36:M37) -> 24114024 | AE38: 95
AE39: =AE38*1.025 -> 97.375
AE40: =AE39*1.025 -> 99.809375

Sheet Do not use - Summary
A1: Summary - Prime Contracts
A2: Year | B2: 2022 | F2: 2023 | R2: 2024 | AD2: 2025
A3: Month | B3: 9 | C3: 10 | D3: 11 | E3: 12 | F3: 1 | G3: 2 | H3: 3 | I3: 4 | J3: 5 | K3: 6 | L3: 7 | M3: 8 | N3: 9 | O3: 10 | P3: 11 | Q3: 12 | R3: 1 | S3: 2 | T3: 3 | U3: 4 | V3: 5 | W3: 6 | X3: 7 | Y3: 8 | Z3: 9 | AA3: 10 | AB3: 11 | AC3: 12 | AD3: 1 | AE3: 2 | AF3: 3 | AG3: 4 | AH3: 5 | AI3: 6 | AJ3: 7 | AK3: 8 | AL3: 9 | AM3: 10 | AN3: 11 | AO3: 12 | AP3: 2 | AQ3: 3 | AR3: 4 | AS3: 5 | AT3: 6 | AU3: 7 | AV3: 8 | AW3: 9 | AX3: 10 | AY3: 11 | AZ3: 12
A4: Working Days | I4: 20 | J4: 22 | K4: 22 | L4: 20 | M4: 23 | N4: 19 | O4: 21 | P4: 20 | Q4: 20
A5: DHS CRCL | AP5: All Periods | AQ5: CY2023 | AR5: CY2024
A6: Charged | B6: ='DHS CRCL'!E83 -> 2080 | C6: ='DHS CRCL'!F83 -> 45618 | D6: ='DHS CRCL'!G83 -> 79599.57 | E6: ='DHS CRCL'!H83 -> 99689.66 | F6: ='DHS CRCL'!I83 -> 114470.18 | G6: ='DHS CRCL'!J83 -> 103617.85 | H6: ='DHS CRCL'!K83 -> 129372.31 | I6: ='DHS CRCL'!L83 -> 122164.97 | ... N6: ='DHS CRCL'!Q83 -> 100546.61 | AP6: =SUM(B6:AD6) -> 1283326.3 | AQ6: =SUM(F6:Q6) -> 1056339.1
A7: Revenue | B7: ='DHS CRCL'!E105 -> 2080 | C7: ='DHS CRCL'!F105 -> 45618 | D7: ='DHS CRCL'!G105 -> 78207.5 | E7: ='DHS CRCL'!H105 -> 106678.77 | F7: ='DHS CRCL'!I105 -> 104269.51 | G7: ='DHS CRCL'!J105 -> 105333.69 | H7: ='DHS CRCL'!K105 -> 129372.31 | I7: ='DHS CRCL'!L105 -> 122164.97 | ... N7: ='DHS CRCL'!Q105 -> 100546.61 | AP7: =SUM(B7:AD7) -> 1280438.5 | AQ7: =SUM(F7:Q7) -> 1047854.2
O8: DHS CRCL OP1 | AP8: All Periods | AQ8: CY2023 | AR8: CY2024
A9: Charged | O9: ='DHS CRCL OP1'!F182 -> 2307.3 | P9: ='DHS CRCL OP1'!G182 -> 128340.84 | Q9: ='DHS CRCL OP1'!H182 -> 136521.19 | R9: ='DHS CRCL OP1'!I182 -> 120057.15 | S9: ='DHS CRCL OP1'!J182 -> 137099.47 | T9: ='DHS CRCL OP1'!K182 -> 107300.02 | U9: ='DHS CRCL OP1'!L182 -> 95743.5 | V9: ='DHS CRCL OP1'!M182 -> 104251.49 | ... Z9: ='DHS CRCL OP1'!Q182 -> 110506.96 | AP9: =SUM(B9:AD9) -> 1282900 | AQ9: =SUM(F9:Q9) -> 267169.33 | AR9: =SUM(R9:AC9) -> 1015730.7
A10: Forecast Rev | R10: ='DHS CRCL OP1'!J138 -> 124150.78 | S10: ='DHS CRCL OP1'!K138 -> 123720.49 | T10: ='DHS CRCL OP1'!L138 -> 118767.42 | U10: ='DHS CRCL OP1'!M138 -> 115249.56 | V10: ='DHS CRCL OP1'!N138 -> 115249.56 | W10: ='DHS CRCL OP1'!O138 -> 109759.92 | X10: ='DHS CRCL OP1'!P138 -> 115249.56 | Y10: ='DHS CRCL OP1'!Q138 -> 110506.96 | Z10: ='DHS CRCL OP1'!R138 -> 118603.8 | AP10: =SUM(B10:AD10) -> 1051258.1 | AQ10: =SUM(F10:Q10) -> 0 | AR10: =SUM(R10:AC10) -> 1051258.1
A11: Revenue | O11: ='DHS CRCL OP1'!F247 -> 0 | P11: ='DHS CRCL OP1'!G247 -> 128340.84 | Q11: ='DHS CRCL OP1'!H247 -> 136521.19 | R11: ='DHS CRCL OP1'!I247 -> 122308.33 | S11: ='DHS CRCL OP1'!J247 -> 137099.47 | T11: ='DHS CRCL OP1'!K247 -> 107300.02 | U11: ='DHS CRCL OP1'!L247 -> 95743.5 | V11: ='DHS CRCL OP1'!M247 -> 104251.49 | ... Z11: ='DHS CRCL OP1'!Q247 -> 110506.96 | AP11: =SUM(B11:AD11) -> 1291112.7 | AQ11: =SUM(F11:Q11) -> 264862.03 | AR11: =SUM(R11:AC11) -> 1026250.7
A12: DHS HSI | AP12: All Periods | AQ12: CY2023 | AR12: CY2024
A13: Forecast Rev | AP13: =SUM(B13:AD13) -> 0 | AQ13: =SUM(F13:Q13) -> 0
A14: Revenue | B14: ='DHS HSI'!E96 -> 0 | C14: ='DHS HSI'!F96 -> 81837 | D14: ='DHS HSI'!G96 -> 81837 | E14: ='DHS HSI'!H96 -> 81837 | F14: ='DHS HSI'!I96 -> 81837 | G14: ='DHS HSI'!J96 -> 81837 | H14: ='DHS HSI'!K96 -> 81837 | I14: ='DHS HSI'!L96 -> 81837 | ... N14: ='DHS HSI'!Q96 -> 81837 | AP14: =SUM(B14:AD14) -> 982044 | AQ14: =SUM(F14:Q14) -> 736533
O15: DHS HSI OP1 | AP15: All Periods | AQ15: CY2023 | AR15: CY2024
A16: Forecast Rev | R16: ='DHS HSI OP1'!J167 -> 167345.93 | S16: ='DHS HSI OP1'!K167 -> 167345.93 | T16: ='DHS HSI OP1'!L167 -> 167345.93 | U16: ='DHS HSI OP1'!M167 -> 167345.93 | V16: ='DHS HSI OP1'!N167 -> 167345.93 | W16: ='DHS HSI OP1'!O167 -> 167345.93 | X16: ='DHS HSI OP1'!P167 -> 167345.93 | Y16: ='DHS HSI OP1'!Q167 -> 167345.92 | Z16: ='DHS HSI OP1'!R167 -> 167345.93 | AP16: =SUM(B16:AD16) -> 1506113.3 | AQ16: =SUM(F16:Q16) -> 0 | AR16: =SUM(R16:AC16) -> 1506113.3
A17: Revenue | O17: ='DHS HSI OP1'!F187 -> 0 | P17: ='DHS HSI OP1'!G187 -> 167345.93 | Q17: ='DHS HSI OP1'!H187 -> 167345.93 | R17: ='DHS HSI OP1'!I187 -> 167345.93 | S17: ='DHS HSI OP1'!J187 -> 167345.93 | T17: ='DHS HSI OP1'!K187 -> 167345.93 | U17: ='DHS HSI OP1'!L187 -> 167345.93 | V17: ='DHS HSI OP1'!M187 -> 167345.93 | ... Z17: ='DHS HSI OP1'!Q187 -> 167345.93 | AP17: =SUM(B17:AD17) -> 1840805.2 | AQ17: =SUM(F17:Q17) -> 334691.85 | AR17: =SUM(R17:AC17) -> 1506113.3
A18: DOI | AP18: All Periods | AQ18: CY2023 | AR18: CY2024
A19: Charged | D19: =DOI!E80 -> 0 | E19: =DOI!F80 -> 6799.31 | F19: =DOI!G80 -> 28450.775 | G19: =DOI!H80 -> 91421.922 | H19: =DOI!I80 -> 140162.23 | I19: =DOI!J80 -> 88017.95 | J19: =DOI!K80 -> 66947.54 | K19: =DOI!L80 -> 56544.185 | ... P19: =DOI!Q80 -> 0 | AP19: =SUM(B19:AD19) -> 643154.51 | AQ19: =SUM(F19:Q19) -> 636355.2
A20: Revenue | D20: =DOI!E99 -> 0 | E20: =DOI!F99 -> 6799.31 | F20: =DOI!G99 -> 28450.16 | G20: =DOI!H99 -> 91417.95 | H20: =DOI!I99 -> 140154.81 | I20: =DOI!J99 -> 88129.64 | J20: =DOI!K99 -> 66947.54 | K20: =DOI!L99 -> 56544.185 | ... P20: =DOI!Q99 -> 0 | AP20: =SUM(B20:AD20) -> 643254.2 | AQ20: =SUM(F20:Q20) -> 636454.89
A21: DOJ ICITAP | AP21: All Periods | AQ21: CY2023 | AR21: CY2024
A22: Charged | E22: ='DOJ ICITAP'!H78 -> 0 | F22: ='DOJ ICITAP'!I78 -> 11589.44 | G22: ='DOJ ICITAP'!J78 -> 11774.725 | H22: ='DOJ ICITAP'!K78 -> 31861.38 | I22: ='DOJ ICITAP'!L78 -> 7186.625 | J22: ='DOJ ICITAP'!M78 -> 8528.45 | K22: ='DOJ ICITAP'!N78 -> 9773.6 | AP22: =SUM(B22:AD22) -> 80714.22 | AQ22: =SUM(F22:Q22) -> 80714.22
A23: Revenue | E23: ='DOJ ICITAP'!H97 -> 0 | F23: ='DOJ ICITAP'!I97 -> 11589.44 | G23: ='DOJ ICITAP'!J97 -> 11774.73 | H23: ='DOJ ICITAP'!K97 -> 29388.6 | I23: ='DOJ ICITAP'!L97 -> 7186.63 | J23: ='DOJ ICITAP'!M97 -> 8528.45 | K23: ='DOJ ICITAP'!N97 -> 9773.6 | AP23: =SUM(B23:AD23) -> 78241.45 | AQ23: =SUM(F23:Q23) -> 78241.45
A24: AMRIID | AP24: All Periods | AQ24: CY2023 | AR24: CY2024
A25: Forecast Rev | AP25: =SUM(B25:AD25) -> 0 | AQ25: =SUM(F25:Q25) -> 0
A26: Revenue | B26: =AMRIID!E93 -> 0 | C26: =AMRIID!F93 -> 61797.13 | D26: =AMRIID!G93 -> 61797.13 | E26: =AMRIID!H93 -> 61797.13 | F26: =AMRIID!I93 -> 61797.13 | G26: =AMRIID!J93 -> 61797.13 | H26: =AMRIID!K93 -> 61797.13 | I26: =AMRIID!L93 -> 61797.13 | ... N26: =AMRIID!Q93 -> 61797.13 | AP26: =SUM(B26:AD26) -> 741565.56 | AQ26: =SUM(F26:Q26) -> 556174.17
N27: AMRIID II | AP27: All Periods | AQ27: CY2023 | AR27: CY2024
A28: Forecast Rev | R28: ='AMRIID 2'!J143 -> 30811.32 | S28: ='AMRIID 2'!K143 -> 30811.32 | T28: ='AMRIID 2'!L143 -> 30811.32 | U28: ='AMRIID 2'!M143 -> 30811.32 | V28: ='AMRIID 2'!N143 -> 30811.32 | W28: ='AMRIID 2'!O143 -> 30811.32 | X28: ='AMRIID 2'!P143 -> 30811.32 | Y28: ='AMRIID 2'!Q143 -> 30811.32 | Z28: ='AMRIID 2'!R143 -> 30811.32 | AP28: =SUM(B28:AD28) -> 277301.88 | AQ28: =SUM(F28:Q28) -> 0 | AR28: =SUM(R28:AC28) -> 277301.88
A29: Revenue | N29: ='AMRIID 2'!F173 -> 0 | O29: ='AMRIID 2'!G173 -> 30811.32 | P29: ='AMRIID 2'!H173 -> 30811.32 | Q29: ='AMRIID 2'!I173 -> 30811.32 | R29: ='AMRIID 2'!J173 -> 30811.32 | S29: ='AMRIID 2'!K173 -> 30811.32 | T29: ='AMRIID 2'!L173 -> 30811.32 | U29: ='AMRIID 2'!M173 -> 30811.32 | ... Z29: ='AMRIID 2'!R173 -> 30811.32 | AP29: =SUM(B29:AD29) -> 369735.84 | AQ29: =SUM(F29:Q29) -> 92433.96 | AR29: =SUM(R29:AC29) -> 277301.88
AA30: AMRIID II.1
A31: Forecast Rev | AA31: ='AMRIID 2.1'!G140 -> 31889.44 | AB31: ='AMRIID 2.1'!H140 -> 31889.44 | AC31: ='AMRIID 2.1'!I140 -> 31889.44 | AD31: ='AMRIID 2.1'!J140 -> 31889.44 | AE31: ='AMRIID 2.1'!K140 -> 31889.44 | AF31: ='AMRIID 2.1'!L140 -> 31889.44 | AG31: ='AMRIID 2.1'!M140 -> 31889.44 | AH31: ='AMRIID 2.1'!N140 -> 31889.44 | ... AL31: ='AMRIID 2.1'!R140 -> 31889.44
A32: Revenue | AA32: ='AMRIID 2.1'!G170 -> 31889.44 | AB32: ='AMRIID 2.1'!H170 -> 31889.44 | AC32: ='AMRIID 2.1'!I170 -> 31889.44
B33: AO Call 1 - RAE Support | AP33: All Periods | AQ33: CY2023 | AR33: CY2024
A34: Charged | B34: ='AO Call 1'!E87 -> 43685.84 | C34: ='AO Call 1'!F87 -> 245030.08 | D34: ='AO Call 1'!G87 -> 251775.76 | E34: ='AO Call 1'!H87 -> 238611.17 | F34: ='AO Call 1'!I87 -> 239007.24 | G34: ='AO Call 1'!J87 -> 243722.59 | H34: ='AO Call 1'!K87 -> 310145.34 | I34: ='AO Call 1'!L87 -> 303822.22 | ... M34: ='AO Call 1'!P87 -> 299461.23 | AP34: =SUM(B34:AD34) -> 3083848.8 | AQ34: =SUM(F34:Q34) -> 2304746
A35: Revenue | B35: ='AO Call 1'!E113 -> 32005.84 | C35: ='AO Call 1'!F113 -> 245030.08 | D35: ='AO Call 1'!G113 -> 250935.76 | E35: ='AO Call 1'!H113 -> 238611.17 | F35: ='AO Call 1'!I113 -> 239007.24 | G35: ='AO Call 1'!J113 -> 241981.63 | H35: ='AO Call 1'!K113 -> 310145.3 | I35: ='AO Call 1'!L113 -> 304110.62 | ... M35: ='AO Call 1'!P113 -> 299461.23 | AP35: =SUM(B35:AD35) -> 3069951.5 | AQ35: =SUM(F35:Q35) -> 2303368.6
M36: AO Call 1.2 - RAE Support | AP36: All Periods | AQ36: CY2023 | AR36: CY2024
A37: Charged | M37: ='AO Call 1.2'!E162 -> 64936.92 | N37: ='AO Call 1.2'!F162 -> 320935.74 | O37: ='AO Call 1.2'!G162 -> 310916.13 | P37: ='AO Call 1.2'!H162 -> 271701.47 | Q37: ='AO Call 1.2'!I162 -> 276832.88 | R37: ='AO Call 1.2'!J162 -> 358178.78 | S37: ='AO Call 1.2'!K162 -> 293879.61 | AP37: =SUM(B37:AD37) -> 1897381.5 | AQ37: =SUM(F37:Q37) -> 1245323.1 | AR37: =SUM(R37:AC37) -> 652058.39
A38: Forecast Rev | R38: ='AO Call 1.2'!J119 -> 341375 | S38: ='AO Call 1.2'!K119 -> 293653.84 | AP38: =SUM(B38:AD38) -> 635028.84 | AQ38: =SUM(F38:Q38) -> 0 | AR38: =SUM(R38:AC38) -> 635028.84
A39: Revenue | M39: ='AO Call 1.2'!E188 -> 64936.92 | N39: ='AO Call 1.2'!F188 -> 320935.74 | O39: ='AO Call 1.2'!G188 -> 310916.13 | P39: ='AO Call 1.2'!H188 -> 271701.47 | Q39: ='AO Call 1.2'!I188 -> 276832.88 | R39: ='AO Call 1.2'!J188 -> 358178.78 | S39: ='AO Call 1.2'!K188 -> 293879.61 | AP39: =SUM(B39:AD39) -> 1897381.5 | AQ39: =SUM(F39:Q39) -> 1245323.1 | AR39: =SUM(R39:AC39) -> 652058.39 | AU39: =SUM(R39:AC39) -> 652058.39
M40: AO Call 1.3 - RAE Support | AP40: All Periods | AQ40: CY2023 | AR40: CY2024
...

Sheet AMRIID 2.1
A2: Project: | B2: USAMRIID
A3: PoP: | B3: 9/30/24 - 9/29/25
A4: Funded Ceiling: | B4: 382673.28
A6: Hours Forecast | F6: Hours
F7: 2024 | J7: 2025
D8: Working Days | F8: 1 | G8: 21 | H8: 20 | I8: 20 | J8: 21 | K8: 20 | L8: 21 | M8: 22 | N8: 23 | O8: 19 | P8: 23 | Q8: 22 | R8: 20
A9: Name | B9: Company | C9: LCAT | D9: Rate | F9: 9 | G9: 10 | H9: 11 | I9: 12 | J9: 1 | K9: 2 | L9: 3 | M9: 4 | N9: 5 | O9: 6 | P9: 7 | Q9: 8 | R9: 9 | S9: Total Hrs CTD | T9: Total Hrs | U9: Rev CTD | V9: Total Rev
A10: Craig Park | B10: TechSur | C10: Program Manager III | D10: 200.61 | S10: =SUM(F10:M10) -> 0 | T10: =SUM(F10:R10) -> 0 | U10: =S10*D10 -> 0 | V10: =SUM(T10*D10) -> 0
A11: Paul Schomburg | B11: TechSur | C11: Program Manager III | D11: 200.61 | F11: 0 | G11: 1 | H11: 1 | I11: 3 | S11: =SUM(F11:M11) -> 5 | T11: =SUM(F11:R11) -> 5 | U11: =S11*D11 -> 1003.05 | V11: =SUM(T11*D11) -> 1003.05
A12: Jonathan Cohodas | B12: TechSur | C12: Data Analyst | D12: 121.78 | F12: 160 | G12: 160 | H12: 160 | I12: 160 | J12: 160 | K12: 160 | L12: 160 | M12: 160 | N12: 160 | O12: 160 | P12: 160 | Q12: 160 | R12: 160 | S12: =SUM(F12:K12) -> 960 | T12: =SUM(F12:R12) -> 2080 | U12: =S12*D12 -> 116908.8 | V12: =SUM(T12*D12) -> 253302.4
S13: =SUM(F13:K13) -> 0 | T13: =SUM(F13:R13) -> 0 | U13: =S13*D13 -> 0 | V13: =SUM(T13*D13) -> 0
S14: =SUM(F14:K14) -> 0 | T14: =SUM(F14:R14) -> 0 | U14: =S14*D14 -> 0 | V14: =SUM(T14*D14) -> 0
S15: =SUM(F15:K15) -> 0 | T15: =SUM(F15:R15) -> 0 | U15: =S15*D15 -> 0 | V15: =SUM(T15*D15) -> 0
S16: =SUM(F16:K16) -> 0 | T16: =SUM(F16:R16) -> 0 | U16: =S16*D16 -> 0 | V16: =SUM(T16*D16) -> 0
S17: =SUM(F17:K17) -> 0 | T17: =SUM(F17:R17) -> 0 | U17: =S17*D17 -> 0 | V17: =SUM(T17*D17) -> 0
S18: =SUM(F18:K18) -> 0 | T18: =SUM(F18:R18) -> 0 | U18: =S18*D18 -> 0 | V18: =SUM(T18*D18) -> 0
S19: =SUM(F19:K19) -> 0 | T19: =SUM(F19:R19) -> 0 | U19: =S19*D19 -> 0 | V19: =SUM(T19*D19) -> 0
S20: =SUM(F20:K20) -> 0 | T20: =SUM(F20:R20) -> 0 | U20: =S20*D20 -> 0 | V20: =SUM(T20*D20) -> 0
S21: =SUM(F21:K21) -> 0 | T21: =SUM(F21:R21) -> 0 | U21: =S21*D21 -> 0 | V21: =SUM(T21*D21) -> 0
S22: =SUM(F22:K22) -> 0 | T22: =SUM(F22:R22) -> 0 | U22: =S22*D22 -> 0 | V22: =SUM(T22*D22) -> 0
S23: =SUM(F23:K23) -> 0 | T23: =SUM(F23:R23) -> 0 | U23: =S23*D23 -> 0 | V23: =SUM(T23*D23) -> 0
S24: =SUM(F24:K24) -> 0 | T24: =SUM(F24:R24) -> 0 | U24: =S24*D24 -> 0 | V24: =SUM(T24*D24) -> 0
... S38: =SUM(F38:K38) -> 0 | T38: =SUM(F38:R38) -> 0 | U38: =S38*D38 -> 0 | V38: =SUM(T38*D38) -> 0
F39: =SUM(F10:F38) -> 160 | G39: =SUM(G10:G38) -> 161 | H39: =SUM(H10:H38) -> 161 | I39: =SUM(I10:I38) -> 163 | J39: =SUM(J10:J38) -> 160 | K39: =SUM(K10:K38) -> 160 | L39: =SUM(L10:L38) -> 160 | M39: =SUM(M10:M38) -> 160 | ... V39: =SUM(V10:V38) -> 254305.45
A41: Hours Actual | F41: Hours
F42: 2024 | J42: 2025
A43: Name | B43: Company | C43: LCAT | D43: Rate | F43: 9 | G43: 10 | H43: 11 | I43: 12 | J43: 1 | K43: 2 | L43: 3 | M43: 4 | N43: 5 | O43: 6 | P43: 7 | Q43: 8 | R43: 9 | S43: Total Hrs CTD | T43: Total Hrs | U43: Rev CTD | V43: Total Rev
A44: Craig Park | B44: TechSur | C44: Program Manager III | D44: 200.61 | S44: =SUM(F44:M44) -> 0 | T44: =SUM(F44:R44) -> 0 | U44: =S44*D44 -> 0 | V44: =SUM(T44*D44) -> 0
A45: Paul Schomburg | B45: TechSur | C45: Program Manager III | D45: 200.61 | F45: 0 | G45: 0 | H45: 1 | I45: 3 | J45: 4 | N45: 4 | O45: 2 | Q45: 1 | S45: =SUM(F45:M45) -> 8 | T45: =SUM(F45:R45) -> 15 | U45: =S45*D45 -> 1604.88 | V45: =SUM(T45*D45) -> 3009.15
A46: Jonathan Cohodas | B46: TechSur | C46: Data Analyst | D46: 121.78 | F46: 160 | G46: 128 | H46: 160 | I46: 160 | J46: 160 | K46: 160 | L46: 160 | M46: 160 | N46: 156 | O46: 152 | P46: 160 | Q46: 136 | R46: 160 | S46: =SUM(F46:K46) -> 928 | T46: =SUM(F46:R46) -> 2012 | U46: =S46*D46 -> 113011.84 | V46: =SUM(T46*D46) -> 245021.36
S47: =SUM(F47:K47) -> 0 | T47: =SUM(F47:R47) -> 0 | U47: =S47*D47 -> 0 | V47: =SUM(T47*D47) -> 0
S48: =SUM(F48:K48) -> 0 | T48: =SUM(F48:R48) -> 0 | U48: =S48*D48 -> 0 | V48: =SUM(T48*D48) -> 0
S49: =SUM(F49:K49) -> 0 | T49: =SUM(F49:R49) -> 0 | U49: =S49*D49 -> 0 | V49: =SUM(T49*D49) -> 0
S50: =SUM(F50:K50) -> 0 | T50: =SUM(F50:R50) -> 0 | U50: =S50*D50 -> 0 | V50: =SUM(T50*D50) -> 0
S51: =SUM(F51:K51) -> 0 | T51: =SUM(F51:R51) -> 0 | U51: =S51*D51 -> 0 | V51: =SUM(T51*D51) -> 0
S52: =SUM(F52:K52) -> 0 | T52: =SUM(F52:R52) -> 0 | U52: =S52*D52 -> 0 | V52: =SUM(T52*D52) -> 0
S53: =SUM(F53:K53) -> 0 | T53: =SUM(F53:R53) -> 0 | U53: =S53*D53 -> 0 | V53: =SUM(T53*D53) -> 0
S54: =SUM(F54:K54) -> 0 | T54: =SUM(F54:R54) -> 0 | U54: =S54*D54 -> 0 | V54: =SUM(T54*D54) -> 0
S55: =SUM(F55:K55) -> 0 | T55: =SUM(F55:R55) -> 0 | U55: =S55*D55 -> 0 | V55: =SUM(T55*D55) -> 0
S56: =SUM(F56:K56) -> 0 | T56: =SUM(F56:R56) -> 0 | U56: =S56*D56 -> 0 | V56: =SUM(T56*D56) -> 0
...

Sheet DHS FLETF
A2: Project: | B2: DHS FLETF
A3: PoP: | B3: 9/30/24 - 9/29/25
A4: Funded Ceiling: | B4: 1457551
A6: Hours Forecast
E7: 2024 | J7: 2025
A8: Name | B8: Company | C8: LCAT | D8: Rate | E8: 8 | F8: 9 | G8: 10 | H8: 11 | I8: 12 | J8: 1 | K8: 2 | L8: 3 | M8: 4 | N8: 5 | O8: 6 | P8: 7 | Q8: 8 | R8: Total Hrs | S8: Rev CTD | T8: Total Rev
A9: Jour OR Analyst Rptg T1 | C9: Senior Consultant II | D9: 134 | G9: 66.666667 | H9: 66.666667 | I9: 66.666667 | J9: 66.666667 | K9: 66.666667 | L9: 66.666667 | M9: 66.666667 | N9: 66.666667 | O9: 66.666667 | P9: 66.666667 | Q9: 66.666667 | R9: =SUM(E9:I9) -> 200 | S9: =Q9*D9 -> 8933.3333 | T9: =SUM(R9*D9) -> 26800
A10: Sr Ops Research Anly T1 | C10: Consulting Manager II | D10: 151.28 | G10: 8.3333333 | H10: 8.3333333 | I10: 8.3333333 | J10: 8.3333333 | K10: 8.3333333 | L10: 8.3333333 | M10: 8.3333333 | N10: 8.3333333 | O10: 8.3333333 | P10: 8.3333333 | Q10: 8.3333333 | R10: =SUM(F10:J10) -> 33.333333 | S10: =Q10*B10 -> 0 | T10: =SUM(R10*B10) -> 0
A11: Jour OR Analyst Rptg T1 | C11: Consultant II | D11: 130 | G11: 308.33333 | H11: 308.33333 | I11: 308.33333 | J11: 308.33333 | K11: 308.33333 | L11: 308.33333 | M11: 308.33333 | N11: 308.33333 | O11: 308.33333 | P11: 308.33333 | Q11: 308.33333 | R11: =SUM(F11:I11) -> 925 | S11: =Q11*B11 -> 0 | T11: =SUM(R11*B11) -> 0
A12: Journ Bus Ops Grp 2 T5 | C12: Senior Consultant II | D12: 144.3 | G12: 154.16667 | H12: 154.16667 | I12: 154.16667 | J12: 154.16667 | K12: 154.16667 | L12: 154.16667 | M12: 154.16667 | N12: 154.16667 | O12: 154.16667 | P12: 154.16667 | Q12: 154.16667 | R12: =SUM(F12:I12) -> 462.5 | S12: =Q12*B12 -> 0 | T12: =SUM(R12*B12) -> 0
A13: Tec Spec Journ ORA T1 | C13: Senior Consultant I | D13: 139 | G13: 320 | H13: 320 | I13: 320 | J13: 320 | K13: 320 | L13: 320 | M13: 320 | N13: 320 | O13: 320 | P13: 320 | Q13: 320
A14: Senior Manager | C14: Director I | D14: 196 | G14: 22.75 | H14: 22.75 | I14: 22.75 | J14: 22.75 | K14: 22.75 | L14: 22.75 | M14: 22.75 | N14: 22.75 | O14: 22.75 | P14: 22.75 | Q14: 22.75
R17: =SUM(E17:I17) -> 0 | S17: =Q17*D17 -> 0 | T17: =SUM(R17*D17) -> 0
R18: =SUM(E18:I18) -> 0 | S18: =Q18*D18 -> 0 | T18: =SUM(R18*D18) -> 0
R19: =SUM(E19:I19) -> 0 | S19: =Q19*D19 -> 0 | T19: =SUM(R19*D19) -> 0
R20: =SUM(E20:I20) -> 0 | S20: =Q20*D20 -> 0 | T20: =SUM(R20*D20) -> 0
R21: =SUM(E21:I21) -> 0 | S21: =Q21*D21 -> 0 | T21: =SUM(R21*D21) -> 0
R22: =SUM(E22:I22) -> 0 | S22: =Q22*D22 -> 0 | T22: =SUM(R22*D22) -> 0
R23: =SUM(E23:I23) -> 0 | S23: =Q23*D23 -> 0 | T23: =SUM(R23*D23) -> 0
R24: =SUM(E24:I24) -> 0 | S24: =Q24*D24 -> 0 | T24: =SUM(R24*D24) -> 0
R25: =SUM(E25:I25) -> 0 | S25: =Q25*D25 -> 0 | T25: =SUM(R25*D25) -> 0
R26: =SUM(E26:I26) -> 0 | S26: =Q26*D26 -> 0 | T26: =SUM(R26*D26) -> 0
R27: =SUM(E27:I27) -> 0 | S27: =Q27*D27 -> 0 | T27: =SUM(R27*D27) -> 0
R28: =SUM(E28:I28) -> 0 | S28: =Q28*D28 -> 0 | T28: =SUM(R28*D28) -> 0
... R38: =SUM(E38:I38) -> 0 | S38: =Q38*D38 -> 0 | T38: =SUM(R38*D38) -> 0
E39: =SUM(E9:E38) -> 0 | F39: =SUM(F9:F38) -> 0 | G39: =SUM(G9:G38) -> 880.25 | H39: =SUM(H9:H38) -> 880.25 | I39: =SUM(I9:I38) -> 880.25 | J39: =SUM(J9:J38) -> 880.25 | K39: =SUM(K9:K38) -> 880.25 | L39: =SUM(L9:L38) -> 880.25 | ... T39: =SUM(T9:T38) -> 26800
A41: Hours Actual
E42: 2024 | J42: 2025
A43: Name | B43: Company | C43: LCAT | D43: Rate | E43: 8 | F43: 9 | G43: 10 | H43: 11 | I43: 12 | J43: 1 | K43: 2 | L43: 3 | M43: 4 | N43: 5 | O43: 6 | P43: 7 | Q43: Total Hrs CTD | R43: Total Hrs | S43: Rev CTD | T43: Total Rev
A44: =A9 -> Jour OR Analyst Rptg T1 | B44: =B9 -> 0 | C44: =C9 -> Senior Consultant II | D44: =D9 -> 134 | R44: =SUM(E44:I44) -> 0 | S44: =Q44*D44 -> 0 | T44: =SUM(R44*D44) -> 0
A45: =A10 -> Sr Ops Research Anly T1 | B45: =B10 -> 0 | C45: =C10 -> Consulting Manager II | D45: =D10 -> 151.28 | R45: =SUM(E45:I45) -> 0 | S45: =Q45*D45 -> 0 | T45: =SUM(R45*D45) -> 0
A46: =A11 -> Jour OR Analyst Rptg T1 | B46: =B11 -> 0 | C46: =C11 -> Consultant II | D46: =D11 -> 130 | R46: =SUM(E46:I46) -> 0 | S46: =Q46*D46 -> 0 | T46: =SUM(R46*D46) -> 0
A47: =A12 -> Journ Bus Ops Grp 2 T5 | B47: =B12 -> 0 | C47: =C12 -> Senior Consultant II | D47: =D12 -> 144.3 | R47: =SUM(E47:I47) -> 0 | S47: =Q47*D47 -> 0 | T47: =SUM(R47*D47) -> 0
A48: =A13 -> Tec Spec Journ ORA T1 | B48: =B13 -> 0 | C48: =C13 -> Senior Consultant I | D48: =D13 -> 139
A49: =A14 -> Senior Manager | B49: =B14 -> 0 | C49: =C14 -> Director I | D49: =D14 -> 196
A50: =A15 -> 0 | B50: =B15 -> 0 | C50: =C15 -> 0 | D50: =D15 -> 0
A51: =A16 -> 0 | B51: =B16 -> 0 | C51: =C16 -> 0 | D51: =D16 -> 0
A52: =A17 -> 0 | B52: =B17 -> 0 | C52: =C17 -> 0 | D52: =D17 -> 0 | R52: =SUM(E52:I52) -> 0 | S52: =Q52*D52 -> 0 | T52: =SUM(R52*D52) -> 0
A53: =A18 -> 0 | B53: =B18 -> 0 | C53: =C18 -> 0 | D53: =D18 -> 0 | R53: =SUM(E53:I53) -> 0 | S53: =Q53*D53 -> 0 | T53: =SUM(R53*D53) -> 0
A54: =A19 -> 0 | B54: =B19 -> 0 | C54: =C19 -> 0 | D54: =D19 -> 0 | R54: =SUM(E54:I54) -> 0 | S54: =Q54*D54 -> 0 | T54: =SUM(R54*D54) -> 0
...

Sheet DOT CTS
A2: Project: | B2: DOT CTS
A3: PoP: | B3: 9/30/24 - 9/30/25
A4: Funded Ceiling: | B4: 399999.96 | C4: =B4/12 -> 33333.33
A6: Hours Forecast
E7: 2024 | J7: 2025
A8: Name | B8: Company | C8: LCAT | D8: Rate | E8: 8 | F8: 9 | G8: 10 | H8: 11 | I8: 12 | J8: 1 | K8: 2 | L8: 3 | M8: 4 | N8: 5 | O8: 6 | P8: 7 | Q8: 8 | R8: Total Hrs | S8: Rev CTD | T8: Total Rev
R9: =SUM(E9:I9) -> 0 | S9: =Q9*D9 -> 0 | T9: =SUM(R9*D9) -> 0
R10: =SUM(E10:J10) -> 0 | S10: =Q10*D10 -> 0 | T10: =SUM(R10*D10) -> 0
R11: =SUM(E11:I11) -> 0 | S11: =Q11*D11 -> 0 | T11: =SUM(R11*D11) -> 0
R12: =SUM(E12:I12) -> 0 | S12: =Q12*D12 -> 0 | T12: =SUM(R12*D12) -> 0
R17: =SUM(E17:I17) -> 0 | S17: =Q17*D17 -> 0 | T17: =SUM(R17*D17) -> 0
R18: =SUM(E18:I18) -> 0 | S18: =Q18*D18 -> 0 | T18: =SUM(R18*D18) -> 0
R19: =SUM(E19:I19) -> 0 | S19: =Q19*D19 -> 0 | T19: =SUM(R19*D19) -> 0
R20: =SUM(E20:I20) -> 0 | S20: =Q20*D20 -> 0 | T20: =SUM(R20*D20) -> 0
R21: =SUM(E21:I21) -> 0 | S21: =Q21*D21 -> 0 | T21: =SUM(R21*D21) -> 0
R22: =SUM(E22:I22) -> 0 | S22: =Q22*D22 -> 0 | T22: =SUM(R22*D22) -> 0
R23: =SUM(E23:I23) -> 0 | S23: =Q23*D23 -> 0 | T23: =SUM(R23*D23) -> 0
R24: =SUM(E24:I24) -> 0 | S24: =Q24*D24 -> 0 | T24: =SUM(R24*D24) -> 0
R25: =SUM(E25:I25) -> 0 | S25: =Q25*D25 -> 0 | T25: =SUM(R25*D25) -> 0
R26: =SUM(E26:I26) -> 0 | S26: =Q26*D26 -> 0 | T26: =SUM(R26*D26) -> 0
... R38: =SUM(E38:I38) -> 0 | S38: =Q38*D38 -> 0 | T38: =SUM(R38*D38) -> 0
E39: =SUM(E9:E38) -> 0 | F39: =SUM(F9:F38) -> 0 | G39: =SUM(G9:G38) -> 0 | H39: =SUM(H9:H38) -> 0 | I39: =SUM(I9:I38) -> 0 | J39: =SUM(J9:J38) -> 0 | K39: =SUM(K9:K38) -> 0 | L39: =SUM(L9:L38) -> 0 | ... T39: =SUM(T9:T38) -> 0
A41: Hours Actual
E42: 2024 | J42: 2025
A43: Name | B43: Company | C43: LCAT | D43: Rate | E43: 8 | F43: 9 | G43: 10 | H43: 11 | I43: 12 | J43: 1 | K43: 2 | L43: 3 | M43: 4 | N43: 5 | O43: 6 | P43: 7 | Q43: Total Hrs CTD | R43: Total Hrs | S43: Rev CTD | T43: Total Rev
A44: =A9 -> 0 | B44: =B9 -> 0 | C44: =C9 -> 0 | D44: =D9 -> 0 | R44: =SUM(E44:I44) -> 0 | S44: =Q44*D44 -> 0 | T44: =SUM(R44*D44) -> 0
A45: =A10 -> 0 | B45: =B10 -> 0 | C45: =C10 -> 0 | D45: =D10 -> 0 | R45: =SUM(E45:I45) -> 0 | S45: =Q45*D45 -> 0 | T45: =SUM(R45*D45) -> 0
A46: =A11 -> 0 | B46: =B11 -> 0 | C46: =C11 -> 0 | D46: =D11 -> 0 | R46: =SUM(E46:I46) -> 0 | S46: =Q46*D46 -> 0 | T46: =SUM(R46*D46) -> 0
A47: =A12 -> 0 | B47: =B12 -> 0 | C47: =C12 -> 0 | D47: =D12 -> 0 | R47: =SUM(E47:I47) -> 0 | S47: =Q47*D47 -> 0 | T47: =SUM(R47*D47) -> 0
A48: =A13 -> 0 | B48: =B13 -> 0 | C48: =C13 -> 0 | D48: =D13 -> 0
A49: =A14 -> 0 | B49: =B14 -> 0 | C49: =C14 -> 0 | D49: =D14 -> 0
A50: =A15 -> 0 | B50: =B15 -> 0 | C50: =C15 -> 0 | D50: =D15 -> 0
A51: =A16 -> 0 | B51: =B16 -> 0 | C51: =C16 -> 0 | D51: =D16 -> 0
A52: =A17 -> 0 | B52: =B17 -> 0 | C52: =C17 -> 0 | D52: =D17 -> 0 | R52: =SUM(E52:I52) -> 0 | S52: =Q52*D52 -> 0 | T52: =SUM(R52*D52) -> 0
A53: =A18 -> 0 | B53: =B18 -> 0 | C53: =C18 -> 0 | D53: =D18 -> 0 | R53: =SUM(E53:I53) -> 0 | S53: =Q53*D53 -> 0 | T53: =SUM(R53*D53) -> 0
A54: =A19 -> 0 | B54: =B19 -> 0 | C54: =C19 -> 0 | D54: =D19 -> 0 | R54: =SUM(E54:I54) -> 0 | S54: =Q54*D54 -> 0 | T54: =SUM(R54*D54) -> 0
A55: =A20 -> 0 | B55: =B20 -> 0 | C55: =C20 -> 0 | D55: =D20 -> 0 | R55: =SUM(E55:I55) -> 0 | S55: =Q55*D55 -> 0 | T55: =SUM(R55*D55) -> 0
A56: =A21 -> 0 | B56: =B21 -> 0 | C56: =C21 -> 0 | D56: =D21 -> 0 | R56: =SUM(E56:I56) -> 0 | S56: =Q56*D56 -> 0 | T56: =SUM(R56*D56) -> 0
A57: =A22 -> 0 | B57: =B22 -> 0 | C57: =C22 -> 0 | D57: =D22 -> 0 | R57: =SUM(E57:I57) -> 0 | S57: =Q57*D57 -> 0 | T57: =SUM(R57*D57) -> 0
A58: =A23 -> 0 | B58: =B23 -> 0 | C58: =C23 -> 0 | D58: =D23 -> 0 | R58: =SUM(E58:I58) -> 0 | S58: =Q58*D58 -> 0 | T58: =SUM(R58*D58) -> 0
...

Sheet AO Call 2.3
A2: Project: | B2: Call 2 - EA Support
A3: PoP: | B3: 9/26/25 - 9/25/26
A4: Funded Ceiling: | B4: 3225811.7
A6: Hours Forecast
F7: 2025 | J7: 2026 | V7: 2027
D8: Working Days | F8: 4 | G8: 21 | H8: 20 | I8: 20 | J8: 21 | K8: 20 | L8: 21 | M8: 22 | N8: 23 | O8: 19 | P8: 23 | Q8: 22 | R8: 18 | S8: 20 | T8: 20 | U8: 20 | V8: 21 | W8: 20 | X8: 21 | Y8: 22 | Z8: 23 | AA8: 19 | AB8: 23 | AC8: 22 | AD8: 18 | AE8: 20 | AF8: 20 | AG8: 20
A9: Name | B9: Company | C9: LCAT | D9: Rate | F9: 9 | G9: 10 | H9: 11 | I9: 12 | J9: 1 | K9: 2 | L9: 3 | M9: 4 | N9: 5 | O9: 6 | P9: 7 | Q9: 8 | R9: 9 | S9: 10 | T9: 11 | U9: 12 | V9: 1 | W9: 2 | X9: 3 | Y9: 4 | Z9: 5 | AA9: 6 | AB9: 7 | AC9: 8 | AD9: 9 | AE9: 10 | AF9: 11 | AG9: 12
A10: Abdelhaq, Haneen | B10: TechSur | C10: Project Manager | D10: 81.63 | F10: 32 | G10: 160 | I10: 160 | J10: 160 | K10: 160 | L10: 160 | M10: =M$8*8 -> 176 | N10: =N$8*8 -> 184 | O10: =O$8*8 -> 152 | P10: =P$8*8 -> 184 | Q10: =Q$8*8 -> 176 | R10: =R$8*8 -> 144 | S10: =($S$8-1)*8 -> 152 | T10: =($S$8-1)*8 -> 152 | U10: =($S$8-1)*8 -> 152 | V10: =($S$8-1)*8 -> 152 | W10: =($S$8-1)*8 -> 152 | X10: =($S$8-1)*8 -> 152 | Y10: =($S$8-1)*8 -> 152 | Z10: =($S$8-1)*8 -> 152 | ... AD10: =($S$8-1)*8 -> 152
A11: Cherukuri, Ajay | B11: TechSur | C11: Data Architect | D11: 97.96 | F11: 32 | G11: 160 | H11: 160 | I11: 160 | J11: 160 | K11: 160 | L11: 160 | M11: =M$8*8 -> 176 | N11: =N$8*8 -> 184 | O11: =O$8*8 -> 152 | P11: =P$8*8 -> 184 | Q11: =Q$8*8 -> 176 | R11: =R$8*8 -> 144
A12: Guglietta, Jayson | B12: TechSur | C12: System Integration Engineer | D12: 154.94 | F12: 32 | G12: 160 | H12: 160 | I12: 160 | J12: 160 | K12: 160 | L12: 160 | M12: =M$8*8 -> 176 | N12: =N$8*8 -> 184 | O12: =O$8*8 -> 152 | P12: =P$8*8 -> 184 | Q12: =Q$8*8 -> 176 | R12: =R$8*8 -> 144 | S12: =($S$8-1)*8 -> 152 | T12: =($S$8-1)*8 -> 152 | U12: =($S$8-1)*8 -> 152 | V12: =($S$8-1)*8 -> 152 | W12: =($S$8-1)*8 -> 152 | X12: =($S$8-1)*8 -> 152 | Y12: =($S$8-1)*8 -> 152 | Z12: =($S$8-1)*8 -> 152 | ... AD12: =($S$8-1)*8 -> 152
A13: Gura, Alec | B13: TechSur | C13: Communications Specialist | D13: 75.92 | F13: 32 | G13: 160 | H13: 160 | I13: 160 | J13: 160 | K13: 160 | L13: 160 | M13: =M$8*8 -> 176 | N13: =N$8*8 -> 184 | O13: =O$8*8 -> 152 | P13: =P$8*8 -> 184 | Q13: =Q$8*8 -> 176 | R13: =R$8*8 -> 144 | S13: =($S$8-1)*8 -> 152 | T13: =($S$8-1)*8 -> 152 | U13: =($S$8-1)*8 -> 152 | V13: =($S$8-1)*8 -> 152 | W13: =($S$8-1)*8 -> 152 | X13: =($S$8-1)*8 -> 152 | Y13: =($S$8-1)*8 -> 152 | Z13: =($S$8-1)*8 -> 152 | ... AD13: =($S$8-1)*8 -> 152
A14: Harkins, Christopher | B14: TechSur | C14: System Integration Engineer | D14: 154.94 | F14: 32 | G14: 160 | H14: 160 | I14: 160 | J14: 160 | K14: 160 | L14: 160 | M14: =M$8*8 -> 176 | N14: =N$8*8 -> 184 | O14: =O$8*8 -> 152 | P14: =P$8*8 -> 184 | Q14: =Q$8*8 -> 176 | R14: =R$8*8 -> 144 | S14: =($S$8-1)*8 -> 152 | T14: =($S$8-1)*8 -> 152 | U14: =($S$8-1)*8 -> 152 | V14: =($S$8-1)*8 -> 152 | W14: =($S$8-1)*8 -> 152 | X14: =($S$8-1)*8 -> 152 | Y14: =($S$8-1)*8 -> 152 | Z14: =($S$8-1)*8 -> 152 | ... AD14: =($S$8-1)*8 -> 152
A15: Indukuri, Ramajyothi | B15: TechSur | C15: Business Analyst - Senior | D15: 122.45 | F15: 32 | G15: 160 | H15: 160 | I15: 160 | J15: 160 | K15: 160 | L15: 160 | M15: =M$8*8 -> 176 | N15: =N$8*8 -> 184 | O15: =O$8*8 -> 152 | P15: =P$8*8 -> 184 | Q15: =Q$8*8 -> 176 | R15: =R$8*8 -> 144 | S15: =($S$8-1)*8 -> 152 | T15: =($S$8-1)*8 -> 152 | U15: =($S$8-1)*8 -> 152 | V15: =($S$8-1)*8 -> 152 | W15: =($S$8-1)*8 -> 152 | X15: =($S$8-1)*8 -> 152 | Y15: =($S$8-1)*8 -> 152 | Z15: =($S$8-1)*8 -> 152 | ... AD15: =($S$8-1)*8 -> 152
A16: Keswani, Navin | B16: TechSur | C16: System Integration Engineer | D16: 154.94 | F16: 32 | G16: 160 | H16: 160 | I16: 160 | J16: 160 | K16: 160 | L16: 160 | M16: =M$8*8 -> 176 | N16: =N$8*8 -> 184 | O16: =O$8*8 -> 152 | P16: =P$8*8 -> 184 | Q16: =Q$8*8 -> 176 | R16: =R$8*8 -> 144 | S16: =($S$8-1)*8 -> 152 | T16: =($S$8-1)*8 -> 152 | U16: =($S$8-1)*8 -> 152 | V16: =($S$8-1)*8 -> 152 | W16: =($S$8-1)*8 -> 152 | X16: =($S$8-1)*8 -> 152 | Y16: =($S$8-1)*8 -> 152 | Z16: =($S$8-1)*8 -> 152 | ... AD16: =($S$8-1)*8 -> 152
A17: Ramamoorthy, Madhavan | B17: TechSur | C17: Systems Architect | D17: 110.2 | F17: 32 | G17: 160 | H17: 160 | I17: 160 | J17: 160 | K17: 160 | L17: 160 | M17: =M$8*8 -> 176 | N17: =N$8*8 -> 184 | O17: =O$8*8 -> 152 | P17: =P$8*8 -> 184 | Q17: =Q$8*8 -> 176 | R17: =R$8*8 -> 144 | S17: =($S$8-1)*8 -> 152 | T17: =($S$8-1)*8 -> 152 | U17: =($S$8-1)*8 -> 152 | V17: =($S$8-1)*8 -> 152 | W17: =($S$8-1)*8 -> 152 | X17: =($S$8-1)*8 -> 152 | Y17: =($S$8-1)*8 -> 152 | Z17: =($S$8-1)*8 -> 152 | ... AD17: =($S$8-1)*8 -> 152
A18: Saleh, Zakariya | B18: TechSur | C18: Systems Architect | D18: 110.2 | F18: 32 | G18: 160 | H18: 160 | I18: 160 | J18: 160 | K18: 160 | L18: 160 | M18: =M$8*8 -> 176 | N18: =N$8*8 -> 184 | O18: =O$8*8 -> 152 | P18: =P$8*8 -> 184 | Q18: =Q$8*8 -> 176 | R18: =R$8*8 -> 144 | S18: =($S$8-1)*8 -> 152 | T18: =($S$8-1)*8 -> 152 | U18: =($S$8-1)*8 -> 152 | V18: =($S$8-1)*8 -> 152 | W18: =($S$8-1)*8 -> 152 | X18: =($S$8-1)*8 -> 152 | Y18: =($S$8-1)*8 -> 152 | Z18: =($S$8-1)*8 -> 152 | ... AD18: =($S$8-1)*8 -> 152
A19: Shewaneh, Yenenesh | B19: TechSur | C19: Data Architect | D19: 97.96 | F19: 32 | G19: 160 | H19: 160 | I19: 160 | J19: 160 | K19: 160 | L19: 160 | M19: =M$8*8 -> 176 | N19: =N$8*8 -> 184 | O19: =O$8*8 -> 152 | P19: =P$8*8 -> 184 | Q19: =Q$8*8 -> 176 | R19: =R$8*8 -> 144 | S19: =($S$8-1)*8 -> 152 | T19: =($S$8-1)*8 -> 152 | U19: =($S$8-1)*8 -> 152 | V19: =($S$8-1)*8 -> 152 | W19: =($S$8-1)*8 -> 152 | X19: =($S$8-1)*8 -> 152 | Y19: =($S$8-1)*8 -> 152 | Z19: =($S$8-1)*8 -> 152 | ... AD19: =($S$8-1)*8 -> 152
A20: Singhal, Tarun | B20: TechSur | C20: Cloud Architect- CDaaS-PaaS-Cloud Hosting | D20: 155.1 | F20: 32 | G20: 160 | H20: 160 | I20: 160 | J20: 160 | K20: 160 | L20: 160 | M20: =M$8*8 -> 176 | N20: =N$8*8 -> 184 | O20: =O$8*8 -> 152 | P20: =P$8*8 -> 184 | Q20: =Q$8*8 -> 176 | R20: =R$8*8 -> 144 | S20: =($S$8-1)*8 -> 152 | T20: =($S$8-1)*8 -> 152 | U20: =($S$8-1)*8 -> 152 | V20: =($S$8-1)*8 -> 152 | W20: =($S$8-1)*8 -> 152 | X20: =($S$8-1)*8 -> 152 | Y20: =($S$8-1)*8 -> 152 | Z20: =($S$8-1)*8 -> 152 | ... AD20: =($S$8-1)*8 -> 152
A21: Tanksale, Vidyadhar | B21: TechSur | C21: Enterprise Architect | D21: 115.47 | F21: 32 | G21: 160 | H21: 160 | I21: 160 | J21: 160 | K21: 160 | L21: 160 | M21: =M$8*8 -> 176 | N21: =N$8*8 -> 184 | O21: =O$8*8 -> 152 | P21: =P$8*8 -> 184 | Q21: =Q$8*8 -> 176 | R21: =R$8*8 -> 144 | S21: =($S$8-1)*8 -> 152 | T21: =($S$8-1)*8 -> 152 | U21: =($S$8-1)*8 -> 152 | V21: =($S$8-1)*8 -> 152 | W21: =($S$8-1)*8 -> 152 | X21: =($S$8-1)*8 -> 152 | Y21: =($S$8-1)*8 -> 152 | Z21: =($S$8-1)*8 -> 152 | ... AD21: =($S$8-1)*8 -> 152
A22: Telang, Sudeep | B22: TechSur | C22: Enterprise Architect | D22: 115.47 | F22: 32 | G22: 160 | H22: 160 | I22: 160 | J22: 160 | K22: 160 | L22: 160 | M22: =M$8*8 -> 176 | N22: =N$8*8 -> 184 | O22: =O$8*8 -> 152 | P22: =P$8*8 -> 184 | Q22: =Q$8*8 -> 176 | R22: =R$8*8 -> 144 | S22: =($S$8-1)*8 -> 152 | T22: =($S$8-1)*8 -> 152 | U22: =($S$8-1)*8 -> 152 | V22: =($S$8-1)*8 -> 152 | W22: =($S$8-1)*8 -> 152 | X22: =($S$8-1)*8 -> 152 | Y22: =($S$8-1)*8 -> 152 | Z22: =($S$8-1)*8 -> 152 | ... AD22: =($S$8-1)*8 -> 152
A23: Welch, Alisa | B23: TechSur | C23: Business Analyst - Senior | D23: 122.45 | F23: 32 | G23: 160 | H23: 160 | I23: 160 | J23: 160 | K23: 160 | L23: 160 | M23: =M$8*8 -> 176 | N23: =N$8*8 -> 184 | O23: =O$8*8 -> 152 | P23: =P$8*8 -> 184 | Q23: =Q$8*8 -> 176 | R23: =R$8*8 -> 144 | S23: =($S$8-1)*8 -> 152 | T23: =($S$8-1)*8 -> 152 | U23: =($S$8-1)*8 -> 152 | V23: =($S$8-1)*8 -> 152 | W23: =($S$8-1)*8 -> 152 | X23: =($S$8-1)*8 -> 152 | Y23: =($S$8-1)*8 -> 152 | Z23: =($S$8-1)*8 -> 152 | ... AD23: =($S$8-1)*8 -> 152
A24: Pedram Farid | B24: TechSur | C24: Enterprise Architect | D24: 115.47 | F24: 32 | G24: 160 | H24: 160 | I24: 160 | J24: 160 | K24: 160 | L24: 160 | M24: =M$8*8 -> 176 | N24: =N$8*8 -> 184 | O24: =O$8*8 -> 152 | P24: =P$8*8 -> 184 | Q24: =Q$8*8 -> 176 | R24: =R$8*8 -> 144 | S24: =($S$8-1)*8 -> 152 | T24: =($S$8-1)*8 -> 152 | U24: =($S$8-1)*8 -> 152 | V24: =($S$8-1)*8 -> 152 | W24: =($S$8-1)*8 -> 152 | X24: =($S$8-1)*8 -> 152 | Y24: =($S$8-1)*8 -> 152 | Z24: =($S$8-1)*8 -> 152 | ... AD24: =($S$8-1)*8 -> 152
A25: Ceenil Kaur | B25: TechSur | C25: Project Manager | D25: 81.63
A26: Carl Mosca | B26: TechSur | C26: System Integration Engineer | D26: 154.94
A27: Mohammad Khan | C27: System Integration Engineer | D27: 154.94
A28: Ranga Lakshminarayanan | C28: Cloud architect | D28: 155.1
A29: Nagarajan Pattabiraman | B29: Systems Integration Engineer | C29: Systems Integration Engineer | D29: 154.94
A30: David Ylizarde | B30: Systems Integration Engineer | C30: Systems Integration Engineer | D30: 154.94
A31: John Bauer | B31: Systems Integration Engineer | C31: Systems Integration Engineer | D31: 154.94
A32: John Castro | B32: Systems Integration Engineer | C32: Systems Integration Engineer | D32: 154.94
F38: =SUM(F10:F37) -> 480 | G38: =SUM(G10:G37) -> 2400 | H38: =SUM(H10:H37) -> 2240 | I38: =SUM(I10:I37) -> 2400 | J38: =SUM(J10:J37) -> 2400 | K38: =SUM(K10:K37) -> 2400 | L38: =SUM(L10:L37) -> 2400 | M38: =SUM(M10:M37) -> 2640 | ... AG38: =SUM(AG10:AG37) -> 0
A40: Hours Actual
F41: 2025 | J41: 2026 | V41: 2027
A42: Name | B42: Company | C42: LCAT | D42: Rate | F42: 9 | G42: 10 | H42: 11 | I42: 12 | J42: 1 | K42: 2 | L42: 3 | M42: 4 | N42: 5 | O42: 6 | P42: 7 | Q42: 8 | R42: 9 | S42: 10 | T42: 11 | U42: 12 | V42: 1 | W42: 2 | X42: 3 | Y42: 4 | Z42: 5 | AA42: 6 | AB42: 7 | AC42: 8 | AD42: 9 | AE42: 10 | AF42: 11 | AG42: 12
A43: =A10 -> Abdelhaq, Haneen | B43: =B10 -> TechSur | C43: =C10 -> Project Manager | D43: =D10 -> 81.63 | G43: 96 | H43: 0 | I43: 0 | J43: 0 | K43: 0 | L43: 0 | M43: 0 | N43: 0 | O43: 0 | P43: 0
A44: =A11 -> Cherukuri, Ajay | B44: =B11 -> TechSur | C44: =C11 -> Data Architect | D44: =D11 -> 97.96 | F44: 0 | G44: 0 | H44: 0 | I44: 0 | J44: 0 | K44: 0 | L44: 0 | M44: 0 | N44: 0 | O44: 0 | P44: 0
A45: =A12 -> Guglietta, Jayson | B45: =B12 -> TechSur | C45: =C12 -> System Integration Engineer | D45: =D12 -> 154.94 | F45: 24 | G45: 88 | H45: 80 | I45: 176 | J45: 160 | K45: 152 | L45: 176 | M45: 176 | N45: 160 | O45: 168 | P45: 144
A46: =A13 -> Gura, Alec | B46: =B13 -> TechSur | C46: =C13 -> Communications Specialist | D46: =D13 -> 75.92 | F46: 16 | G46: 96 | H46: 80 | I46: 160 | J46: 160 | K46: 152 | L46: 168 | M46: 176 | N46: 160 | O46: 152 | P46: 176
A47: =A14 -> Harkins, Christopher | B47: =B14 -> TechSur | C47: =C14 -> System Integration Engineer | D47: =D14 -> 154.94 | F47: 16 | G47: 96 | H47: 80 | I47: 176 | J47: 128 | K47: 152 | L47: 176 | M47: 176 | N47: 160 | O47: 168 | P47: 176
A48: =A15 -> Indukuri, Ramajyothi | B48: =B15 -> TechSur | C48: =C15 -> Business Analyst - Senior | D48: =D15 -> 122.45 | F48: 24 | G48: 96 | H48: 80 | I48: 176 | J48: 160 | K48: 152 | L48: 176 | M48: 176 | N48: 160 | O48: 168 | P48: 176
...

Sheet AO Call 4.3
A2: Project: | B2: Call 4 - MFA Support
A3: PoP: | B3: 4/10/26-4/9/27
A4: Funded Ceiling: | B4: 1941638.4
A5: Contract Ceiling | B5: 1941638.4
A6: Hours Forecast
D7: Working Days | E7: 20 | F7: 22 | G7: 22 | H7: 20 | I7: 23 | J7: 19 | K7: 21 | L7: 21 | M7: 20 | N7: 22 | O7: 20 | P7: 21 | Q7: 20 | R7: 22 | S7: 22 | T7: 20 | U7: 23 | V7: 19 | W7: 21 | X7: 21 | Y7: 20 | Z7: 22 | AA7: 20 | AB7: 21 | AC7: 20 | AD7: 22 | AE7: 22 | AF7: 20 | AG7: 23 | AH7: 19 | AI7: 21 | AJ7: 21 | AK7: 20 | AL7: 22 | AM7: 20 | AN7: 21 | AO7: 20 | AP7: 22 | AQ7: 22 | AR7: 20 | AS7: 23 | AT7: 19 | AU7: 21 | AV7: 21 | AW7: 20
E8: 2026 | N8: 2027 | Z8: 2028 | AL8: 2029
A9: Name | B9: Company | C9: LCAT | D9: Rate | E9: 4 | F9: 5 | G9: 6 | H9: 7 | I9: 8 | J9: 9 | K9: 10 | L9: 11 | M9: 12 | N9: 1 | O9: 2 | P9: 3 | Q9: 4 | R9: 5 | S9: 6 | T9: 7 | U9: 8 | V9: 9 | W9: 10 | X9: 11 | Y9: 12 | Z9: 1 | AA9: 2 | AB9: 3 | AC9: 4 | AD9: 5 | AE9: 6 | AF9: 7 | AG9: 8 | AH9: 9 | AI9: 10 | AJ9: 11 | AK9: 12 | AL9: 1 | AM9: 2 | AN9: 3 | AO9: 4 | AP9: 5 | AQ9: 6 | AR9: 7 | AS9: 8 | AT9: 9 | AU9: 10 | AV9: 11 | AW9: 12
A10: Bandapally, Sunil Kumar | B10: TechSur | C10: Systems Integration Engineer | D10: 154.94 | E10: 120 | F10: 159.6 | G10: =(G$7-1)*8 -> 168 | H10: =(H$7-1)*8 -> 152 | I10: =(I$7-1)*8 -> 176 | J10: =(J$7-1)*8 -> 144 | K10: =(K$7-1)*8 -> 160 | L10: =(L$7-1)*8 -> 160 | M10: =(M$7-1)*8 -> 152 | N10: =(N$7-1)*8 -> 168 | ... P10: =(P$7-1)*8 -> 160 | Q10: 64
A11: Gupta, Sangamewar | B11: TechSur | C11: Systems Integration Engineer | D11: 154.94 | E11: 120 | F11: 159.6 | G11: =(G$7-1)*8 -> 168 | H11: =(H$7-1)*8 -> 152 | I11: =(I$7-1)*8 -> 176 | J11: =(J$7-1)*8 -> 144 | K11: =(K$7-1)*8 -> 160 | L11: =(L$7-1)*8 -> 160 | M11: =(M$7-1)*8 -> 152 | N11: =(N$7-1)*8 -> 168 | ... P11: =(P$7-1)*8 -> 160 | Q11: 64
A12: Kakhramon, Talibdjanov | B12: TechSur | C12: Systems Integration Engineer | D12: 154.94 | E12: 120 | F12: 159.6 | G12: =(G$7-1)*8 -> 168 | H12: =(H$7-1)*8 -> 152 | I12: =(I$7-1)*8 -> 176 | J12: =(J$7-1)*8 -> 144 | K12: =(K$7-1)*8 -> 160 | L12: =(L$7-1)*8 -> 160 | M12: =(M$7-1)*8 -> 152 | N12: =(N$7-1)*8 -> 168 | ... P12: =(P$7-1)*8 -> 160 | Q12: 64
A13: Nazir, Muhammad | B13: TechSur | C13: Systems Integration Engineer | D13: 154.94 | E13: 120 | F13: 159.6 | G13: =(G$7-1)*8 -> 168 | H13: =(H$7-1)*8 -> 152 | I13: =(I$7-1)*8 -> 176 | J13: =(J$7-1)*8 -> 144 | K13: =(K$7-1)*8 -> 160 | L13: =(L$7-1)*8 -> 160 | M13: =(M$7-1)*8 -> 152 | N13: =(N$7-1)*8 -> 168 | ... P13: =(P$7-1)*8 -> 160 | Q13: 64
A14: Verma, Narayan Kumar | B14: TechSur | C14: Systems Integration Engineer | D14: 154.94 | E14: 120 | F14: 159.6 | G14: =(G$7-1)*8 -> 168 | H14: =(H$7-1)*8 -> 152 | I14: =(I$7-1)*8 -> 176 | J14: =(J$7-1)*8 -> 144 | K14: =(K$7-1)*8 -> 160 | L14: =(L$7-1)*8 -> 160 | M14: =(M$7-1)*8 -> 152 | N14: =(N$7-1)*8 -> 168 | ... P14: =(P$7-1)*8 -> 160 | Q14: 64
A15: Holcomb, Lauryn | B15: TechSur | C15: Project Manager | D15: 81.63 | E15: 120 | F15: 159.6 | G15: =(G$7-1)*8 -> 168 | H15: =(H$7-1)*8 -> 152 | I15: =(I$7-1)*8 -> 176 | J15: =(J$7-1)*8 -> 144 | K15: =(K$7-1)*8 -> 160 | L15: =(L$7-1)*8 -> 160 | M15: =(M$7-1)*8 -> 152 | N15: =(N$7-1)*8 -> 168 | ... P15: =(P$7-1)*8 -> 160 | Q15: 64
E40: =SUM(E10:E39) -> 720 | F40: =SUM(F10:F39) -> 957.6 | G40: =SUM(G10:G39) -> 1008 | H40: =SUM(H10:H39) -> 912 | I40: =SUM(I10:I39) -> 1056 | J40: =SUM(J10:J39) -> 864 | K40: =SUM(K10:K39) -> 960 | L40: =SUM(L10:L39) -> 960 | ... AW40: =SUM(AW10:AW39) -> 0
A42: Hours Actual
E43: 2026 | N43: 2027 | Z43: 2028 | AL43: 2029
A44: Name | B44: Company | C44: LCAT | D44: Rate | E44: 4 | F44: 5 | G44: 6 | H44: 7 | I44: 8 | J44: 9 | K44: 10 | L44: 11 | M44: 12 | N44: 1 | O44: 2 | P44: 3 | Q44: 4 | R44: 5 | S44: 6 | T44: 7 | U44: 8 | V44: 9 | W44: 10 | X44: 11 | Y44: 12 | Z44: 1 | AA44: 2 | AB44: 3 | AC44: 4 | AD44: 5 | AE44: 6 | AF44: 7 | AG44: 8 | AH44: 9 | AI44: 10 | AJ44: 11 | AK44: 12 | AL44: 1 | AM44: 2 | AN44: 3 | AO44: 4 | AP44: 5 | AQ44: 6 | AR44: 7 | AS44: 8 | AT44: 9 | AU44: 10 | AV44: 11 | AW44: 12
A45: =A10 -> Bandapally, Sunil Kumar | B45: =B10 -> TechSur | C45: =C10 -> Systems Integration Engineer | D45: =D10 -> 154.94 | E45: 118 | F45: 158 | G45: 168 | H45: 176
A46: =A11 -> Gupta, Sangamewar | B46: =B11 -> TechSur | C46: =C11 -> Systems Integration Engineer | D46: =D11 -> 154.94 | E46: 120 | F46: 152 | G46: 160 | H46: 168
A47: =A12 -> Kakhramon, Talibdjanov | B47: =B12 -> TechSur | C47: =C12 -> Systems Integration Engineer | D47: =D12 -> 154.94 | E47: 120 | F47: 152 | G47: 160 | H47: 176
A48: =A13 -> Nazir, Muhammad | B48: =B13 -> TechSur | C48: =C13 -> Systems Integration Engineer | D48: =D13 -> 154.94 | E48: 120 | F48: 120 | G48: 168 | H48: 176
A49: =A14 -> Verma, Narayan Kumar | B49: =B14 -> TechSur | C49: =C14 -> Systems Integration Engineer | D49: =D14 -> 154.94 | E49: 120 | F49: 160 | G49: 168 | H49: 176
A50: =A15 -> Holcomb, Lauryn | B50: =B15 -> TechSur | C50: =C15 -> Project Manager | D50: =D15 -> 81.63 | E50: 112 | F50: 160 | G50: 168 | H50: 176
A51: =A17 -> 0 | B51: =B17 -> 0 | C51: =C17 -> 0 | D51: =D17 -> 0
A52: =A18 -> 0 | B52: =B18 -> 0 | C52: =C18 -> 0 | D52: =D18 -> 0
A53: =A19 -> 0 | B53: =B19 -> 0 | C53: =C19 -> 0 | D53: =D19 -> 0
A54: =A20 -> 0 | B54: =B20 -> 0 | C54: =C20 -> 0 | D54: =D20 -> 0
E75: =SUM(E45:E74) -> 710 | F75: =SUM(F45:F74) -> 902 | G75: =SUM(G45:G74) -> 992 | H75: =SUM(H45:H74) -> 1048 | I75: =SUM(I45:I74) -> 0 | J75: =SUM(J45:J74) -> 0 | K75: =SUM(K45:K74) -> 0 | L75: =SUM(L45:L74) -> 0 | ... AW75: =SUM(AW45:AW74) -> 0
A77: Forecast Revenue by Resource
E78: 2026 | N78: 2027 | Z78: 2028 | AL78: 2029
A79: Name | B79: Company | C79: LCAT | D79: Rate | E79: 4 | F79: 5 | G79: 6 | H79: 7 | I79: 8 | J79: 9 | K79: 10 | L79: 11 | M79: 12 | N79: 1 | O79: 2 | P79: 3 | Q79: 4 | R79: 5 | S79: 6 | T79: 7 | U79: 8 | V79: 9 | W79: 10 | X79: 11 | Y79: 12 | Z79: 1 | AA79: 2 | AB79: 3 | AC79: 4 | AD79: 5 | AE79: 6 | AF79: 7 | AG79: 8 | AH79: 9 | AI79: 10 | AJ79: 11 | AK79: 12 | AL79: 1 | AM79: 2 | AN79: 3 | AO79: 4 | AP79: 5 | AQ79: 6 | AR79: 7 | AS79: 8 | AT79: 9 | AU79: 10 | AV79: 11 | AW79: 12
A80: =A10 -> Bandapally, Sunil Kumar | B80: =B10 -> TechSur | C80: =C10 -> Systems Integration Engineer | D80: =D10 -> 154.94 | E80: =$D80*E10 -> 18592.8 | F80: =$D80*F10 -> 24728.424 | G80: =$D80*G10 -> 26029.92 | H80: =$D80*H10 -> 23550.88 | I80: =$D80*I10 -> 27269.44 | J80: =$D80*J10 -> 22311.36 | K80: =$D80*K10 -> 24790.4 | L80: =$D80*L10 -> 24790.4 | ... Q80: =$D80*Q10 -> 9916.16 | R80: =R10*$D10 -> 0 | S80: =S10*$D10 -> 0 | T80: =T10*$D10 -> 0 | U80: =U10*$D10 -> 0 | V80: =V10*$D10 -> 0 | W80: =W10*$D10 -> 0 | X80: =X10*$D10 -> 0 | Y80: =Y10*$D10 -> 0 | ... AO80: =AO10*$D10 -> 0
A81: =A11 -> Gupta, Sangamewar | B81: =B11 -> TechSur | C81: =C11 -> Systems Integration Engineer | D81: =D11 -> 154.94 | E81: =$D81*E11 -> 18592.8 | F81: =$D81*F11 -> 24728.424 | G81: =$D81*G11 -> 26029.92 | H81: =$D81*H11 -> 23550.88 | I81: =$D81*I11 -> 27269.44 | J81: =$D81*J11 -> 22311.36 | K81: =$D81*K11 -> 24790.4 | L81: =$D81*L11 -> 24790.4 | ... Q81: =$D81*Q11 -> 9916.16 | R81: =R11*$D11 -> 0 | S81: =S11*$D11 -> 0 | T81: =T11*$D11 -> 0 | U81: =U11*$D11 -> 0 | V81: =V11*$D11 -> 0 | W81: =W11*$D11 -> 0 | X81: =X11*$D11 -> 0 | Y81: =Y11*$D11 -> 0 | ... AO81: =AO11*$D11 -> 0
A82: =A12 -> Kakhramon, Talibdjanov | B82: =B12 -> TechSur | C82: =C12 -> Systems Integration Engineer | D82: =D12 -> 154.94 | E82: =$D82*E12 -> 18592.8 | F82: =$D82*F12 -> 24728.424 | G82: =$D82*G12 -> 26029.92 | H82: =$D82*H12 -> 23550.88 | I82: =$D82*I12 -> 27269.44 | J82: =$D82*J12 -> 22311.36 | K82: =$D82*K12 -> 24790.4 | L82: =$D82*L12 -> 24790.4 | ... Q82: =$D82*Q12 -> 9916.16 | R82: =R12*$D12 -> 0 | S82: =S12*$D12 -> 0 | T82: =T12*$D12 -> 0 | U82: =U12*$D12 -> 0 | V82: =V12*$D12 -> 0 | W82: =W12*$D12 -> 0 | X82: =X12*$D12 -> 0 | Y82: =Y12*$D12 -> 0 | ... AO82: =AO12*$D12 -> 0
A83: =A14 -> Verma, Narayan Kumar | B83: =B14 -> TechSur | C83: =C14 -> Systems Integration Engineer | D83: =D14 -> 154.94 | E83: =$D83*E13 -> 18592.8 | F83: =$D83*F13 -> 24728.424 | G83: =$D83*G13 -> 26029.92 | H83: =$D83*H13 -> 23550.88 | I83: =$D83*I13 -> 27269.44 | J83: =$D83*J13 -> 22311.36 | K83: =$D83*K13 -> 24790.4 | L83: =$D83*L13 -> 24790.4 | ... Q83: =$D83*Q13 -> 9916.16 | R83: =R13*$D14 -> 0 | S83: =S13*$D14 -> 0 | T83: =T13*$D14 -> 0 | U83: =U13*$D14 -> 0 | V83: =V13*$D14 -> 0 | W83: =W13*$D14 -> 0 | X83: =X13*$D14 -> 0 | Y83: =Y13*$D14 -> 0 | ... AO83: =AO13*$D14 -> 0
A84: =A15 -> Holcomb, Lauryn | B84: =B15 -> TechSur | C84: =C15 -> Project Manager | D84: =D15 -> 81.63 | E84: =$D84*E15 -> 9795.6 | F84: =$D84*F14 -> 13028.148 | G84: =$D84*G14 -> 13713.84 | H84: =$D84*H14 -> 12407.76 | I84: =$D84*I14 -> 14366.88 | J84: =$D84*J14 -> 11754.72 | K84: =$D84*K14 -> 13060.8 | L84: =$D84*L14 -> 13060.8 | M84: =$D84*M14 -> 12407.76 | ... Q84: =$D84*Q14 -> 5224.32 | R84: =R14*$D15 -> 0 | S84: =S14*$D15 -> 0 | T84: =T14*$D15 -> 0 | U84: =U14*$D15 -> 0 | V84: =V14*$D15 -> 0 | W84: =W14*$D15 -> 0 | X84: =X14*$D15 -> 0 | Y84: =Y14*$D15 -> 0 | ... AO84: =AO14*$D15 -> 0
A85: =A16 -> 0 | B85: =B16 -> 0 | C85: =C16 -> 0 | D85: =D16 -> 0 | E85: =$D85*E15 -> 0 | F85: =$D85*F15 -> 0 | G85: =$D85*G15 -> 0 | H85: =$D85*H15 -> 0 | I85: =$D85*I15 -> 0 | J85: =$D85*J15 -> 0 | K85: =$D85*K15 -> 0 | L85: =$D85*L15 -> 0 | M85: =$D85*M15 -> 0 | N85: =$D85*N17 -> 0 | O85: =$D85*O17 -> 0 | P85: =$D85*P17 -> 0 | Q85: =$D85*Q17 -> 0 | R85: =R17*$D16 -> 0 | S85: =S17*$D16 -> 0 | T85: =T17*$D16 -> 0 | U85: =U17*$D16 -> 0 | V85: =V17*$D16 -> 0 | W85: =W17*$D16 -> 0 | X85: =X17*$D16 -> 0 | Y85: =Y17*$D16 -> 0 | ... AO85: =AO17*$D16 -> 0
A86: =A17 -> 0 | B86: =B17 -> 0 | C86: =C17 -> 0 | D86: =D17 -> 0 | E86: =$D86*E16 -> 0 | F86: =$D86*F16 -> 0 | G86: =$D86*G16 -> 0 | H86: =$D86*H16 -> 0 | I86: =$D86*I16 -> 0 | J86: =$D86*J16 -> 0 | K86: =$D86*K16 -> 0 | L86: =$D86*L16 -> 0 | ... Q86: =$D86*Q16 -> 0 | R86: =R16*$D17 -> 0 | S86: =S16*$D17 -> 0 | T86: =T16*$D17 -> 0 | U86: =U16*$D17 -> 0 | V86: =V16*$D17 -> 0 | W86: =W16*$D17 -> 0 | X86: =X16*$D17 -> 0 | Y86: =Y16*$D17 -> 0 | ... AO86: =AO16*$D17 -> 0
A87: =A18 -> 0 | B87: =B18 -> 0 | C87: =C18 -> 0 | D87: =D18 -> 0 | E87: =$D87*E17 -> 0 | F87: =$D87*F17 -> 0 | G87: =$D87*G17 -> 0 | H87: =$D87*H17 -> 0 | I87: =$D87*I17 -> 0 | J87: =$D87*J17 -> 0 | K87: =$D87*K17 -> 0 | L87: =$D87*L17 -> 0 | ... AO87: =$D87*AO17 -> 0
...

Sheet AO Call 13.1
A2: Project: | B2: Call 13 - DevSecOps
A3: PoP: | B3: 9/13/25 - 9/12/26 | C3: OP2: 9/13/26 - 9/12/27
A4: Funded Ceiling: | B4: 1491977.3
A6: Hours Forecast
D7: Working Days | E7: 22 | F7: 18 | G7: 21 | H7: 20 | I7: 20 | J7: 21 | K7: 20 | L7: 21 | M7: 22 | N7: 23 | O7: 19 | P7: 23 | Q7: 22 | R7: 18 | S7: 21 | T7: 20 | U7: 20 | V7: 21 | W7: 20 | X7: 21 | Y7: 22 | Z7: 23 | AA7: 19 | AB7: 23 | AC7: 22 | AD7: 18 | AE7: 21 | AF7: 20 | AG7: 20 | AH7: 21 | AI7: 20 | AJ7: 21 | AK7: 22 | AL7: 23 | AM7: 19 | AN7: 23 | AO7: 22 | AP7: 18 | AQ7: 21 | AR7: 20 | AS7: 20
E8: 2025 | J8: 2026 | V8: 2027 | AH8: 2028
A9: Name | B9: Company | C9: LCAT | D9: Rate | E9: 8 | F9: 9 | G9: 10 | H9: 11 | I9: 12 | J9: 1 | K9: 2 | L9: 3 | M9: 4 | N9: 5 | O9: 6 | P9: 7 | Q9: 8 | R9: 9 | S9: 10 | T9: 11 | U9: 12 | V9: 1 | W9: 2 | X9: 3 | Y9: 4 | Z9: 5 | AA9: 6 | AB9: 7 | AC9: 8 | AD9: 9 | AE9: 10 | AF9: 11 | AG9: 12 | AH9: 1 | AI9: 2 | AJ9: 3 | AK9: 4 | AL9: 5 | AM9: 6 | AN9: 7 | AO9: 8 | AP9: 9 | AQ9: 10 | AR9: 11 | AS9: 12
A10: Bulchandani, Kapil | B10: TechSur | C10: Systems Integration Engineer | D10: 154.94 | F10: 80 | G10: 160 | H10: 80 | I10: 160 | J10: =(J$7-1)*8 -> 160 | K10: 80 | T10: =(T$7-1)*8 -> 152 | U10: =(U$7-1)*8 -> 152 | V10: =(V$7-1)*8 -> 160 | W10: =(W$7-1)*8 -> 152 | X10: =(X$7-1)*8 -> 160 | Y10: =(Y$7-1)*8 -> 168 | Z10: =(Z$7-1)*8 -> 176 | AA10: =(AA$7-1)*8 -> 144 | ... AS10: =(AS$7-1)*8 -> 152
A11: Gohil, Shailendra | B11: TechSur | C11: Systems Integration Engineer | D11: 154.94 | F11: 80 | G11: 160 | H11: 80 | I11: 160 | J11: =(J$7-1)*8 -> 160 | K11: =(K$7-1)*8 -> 152 | L11: =L12*0.5 -> 80 | M11: 20 | N11: 20 | O11: 20 | P11: 20 | Q11: 20 | R11: 20 | T11: =(T$7-1)*8 -> 152 | U11: =(U$7-1)*8 -> 152 | V11: =(V$7-1)*8 -> 160 | W11: =(W$7-1)*8 -> 152 | X11: =(X$7-1)*8 -> 160 | Y11: =(Y$7-1)*8 -> 168 | Z11: =(Z$7-1)*8 -> 176 | AA11: =(AA$7-1)*8 -> 144 | ... AS11: =(AS$7-1)*8 -> 152
A12: Gupta, Madhur | B12: TechSur | C12: Business Analyst - Senior | D12: 122.45 | F12: 80 | G12: 160 | H12: 80 | I12: 160 | J12: =(J$7-1)*8 -> 160 | K12: =(K$7-1)*8 -> 152 | L12: =(L$7-1)*8 -> 160 | M12: =(M$7-1)*8 -> 168 | N12: =(N$7-1)*8 -> 176 | O12: =(O$7-1)*8 -> 144 | P12: =(P$7-1)*8 -> 176 | Q12: =(Q$7-1)*8 -> 168 | R12: 72
A13: Jain, Harsh | B13: JB Management | C13: Systems Integration Engineer | D13: 154.94 | F13: 80 | G13: 160 | H13: 80 | I13: 160 | J13: =(J$7-1)*8 -> 160 | K13: =(K$7-1)*8 -> 152 | L13: =(L$7-1)*8 -> 160 | M13: =(M$7-1)*8 -> 168 | N13: =(N$7-1)*8 -> 176 | O13: =(O$7-1)*8 -> 144 | P13: =((P$7-1)*8)-40 -> 136 | Q13: =(Q$7-1)*8 -> 168 | R13: 72
A14: Kumar, Manoj | B14: JB Management | C14: Systems Integration Engineer | D14: 154.94 | F14: 80 | G14: 160 | H14: 80 | I14: 160 | J14: =(J$7-1)*8 -> 160 | K14: =152-40 -> 112
A15: Sivaprakasam, Vijay | B15: TechSur | C15: Systems Integration Engineer | D15: 154.94 | F15: 80 | G15: 160 | H15: 80 | I15: 160 | J15: =(J$7-1)*8 -> 160 | K15: =(K$7-1)*8 -> 152 | L15: =(L$7-1)*8 -> 160 | M15: =(M$7-1)*8 -> 168 | N15: =((N$7-1)*8)-40 -> 136 | O15: =(O$7-1)*8 -> 144 | P15: =(P$7-1)*8 -> 176 | Q15: =(Q$7-1)*8 -> 168 | R15: 72
A16: Molabanti, Mohana | B16: TechSur | C16: Systems Integration Engineer | D16: 154.94 | K16: 40 | L16: =(L$7-1)*8 -> 160 | M16: =(M$7-1)*8 -> 168 | N16: =(N$7-1)*8 -> 176 | O16: =(O$7-1)*8 -> 144 | P16: =(P$7-1)*8 -> 176 | Q16: =(Q$7-1)*8 -> 168 | R16: 72
A17: Awodeu, Olusola | B17: TechSur | C17: Systems Integration Engineer | D17: 154.94 | K17: 40 | L17: =(L$7-1)*8 -> 160 | M17: =(M$7-1)*8 -> 168 | N17: =((N$7-1)*8)-24 -> 152 | O17: =(O$7-1)*8 -> 144 | P17: =(P$7-1)*8 -> 176 | Q17: =(Q$7-1)*8 -> 168 | R17: 72
A18: Devarshi Pathak | B18: TechSur | C18: Systems Integration Engineer | D18: 154.94 | P18: 80 | Q18: 168 | R18: 72
E40: =SUM(E10:E39) -> 0 | F40: =SUM(F10:F39) -> 480 | G40: =SUM(G10:G39) -> 960 | H40: =SUM(H10:H39) -> 480 | I40: =SUM(I10:I39) -> 960 | J40: =SUM(J10:J39) -> 960 | K40: =SUM(K10:K39) -> 880 | L40: =SUM(L10:L39) -> 880 | ... R40: =SUM(R10:R39) -> 452
A42: Hours Actual
E43: 2025 | J43: 2026 | V43: 2026 | AH43: 2027
A44: Name | B44: Company | C44: LCAT | D44: Rate | E44: 8 | F44: 9 | G44: 10 | H44: 11 | I44: 12 | J44: 1 | K44: 2 | L44: 3 | M44: 4 | N44: 5 | O44: 6 | P44: 7 | Q44: 8 | R44: 9 | S44: 10 | T44: 11 | U44: 12 | V44: 1 | W44: 2 | X44: 3 | Y44: 4 | Z44: 5 | AA44: 6 | AB44: 7 | AC44: 8 | AD44: 9 | AE44: 10 | AF44: 11 | AG44: 12 | AH44: 1 | AI44: 2 | AJ44: 3 | AK44: 4 | AL44: 5 | AM44: 6 | AN44: 7 | AO44: 8 | AP44: 9 | AQ44: 10 | AR44: 11 | AS44: 12
A45: =A10 -> Bulchandani, Kapil | B45: =B10 -> TechSur | C45: =C10 -> Systems Integration Engineer | D45: =D10 -> 154.94 | F45: 96 | G45: 96 | H45: 80 | I45: 176 | J45: 118.5 | K45: 38 | L45: 0 | M45: 0 | N45: 0 | O45: 0 | P45: 0
A46: =A11 -> Gohil, Shailendra | B46: =B11 -> TechSur | C46: =C11 -> Systems Integration Engineer | D46: =D11 -> 154.94 | F46: 96 | G46: 96 | H46: 20 | I46: 138 | J46: 112 | K46: 130 | L46: 63 | M46: 11 | N46: 0 | O46: 0 | P46: 0
A47: =A12 -> Gupta, Madhur | B47: =B12 -> TechSur | C47: =C12 -> Business Analyst - Senior | D47: =D12 -> 122.45 | F47: 92 | G47: 0 | H47: 80 | I47: 148 | J47: 160 | K47: 152 | L47: 176 | M47: 176 | N47: 160 | O47: 168 | P47: 176
A48: =A13 -> Jain, Harsh | B48: =B13 -> JB Management | C48: =C13 -> Systems Integration Engineer | D48: =D13 -> 154.94 | F48: 96 | G48: 96 | H48: 80 | I48: 176 | J48: 160 | K48: 152 | L48: 168 | M48: 176 | N48: 160 | O48: 168 | P48: 128
A49: =A14 -> Kumar, Manoj | B49: =B14 -> JB Management | C49: =C14 -> Systems Integration Engineer | D49: =D14 -> 154.94 | F49: 96 | G49: 96 | H49: 80 | I49: 176 | J49: 160 | K49: 136 | L49: 0 | M49: 0 | N49: 0 | O49: 0 | P49: 0
A50: =A15 -> Sivaprakasam, Vijay | B50: =B15 -> TechSur | C50: =C15 -> Systems Integration Engineer | D50: =D15 -> 154.94 | F50: 96 | G50: 96 | H50: 32 | I50: 176 | J50: 160 | K50: 112 | L50: 176 | M50: 176 | N50: 160 | O50: 168 | P50: 176
A51: =A16 -> Molabanti, Mohana | B51: =B16 -> TechSur | C51: =C16 -> Systems Integration Engineer | D51: =D16 -> 154.94 | K51: 16 | L51: 176 | M51: 176 | N51: 160 | O51: 168 | P51: 172
A52: =A17 -> Awodeu, Olusola | B52: =B17 -> TechSur | C52: =C17 -> Systems Integration Engineer | D52: =D17 -> 154.94 | K52: 16 | L52: 176 | M52: 176 | N52: 160 | O52: 168 | P52: 176
A53: =A18 -> Devarshi Pathak | B53: =B18 -> TechSur | C53: =C18 -> Systems Integration Engineer | D53: =D18 -> 154.94
A54: =A19 -> 0 | B54: =B19 -> 0 | C54: =C19 -> 0 | D54: =D19 -> 0
E75: =SUM(E45:E74) -> 0 | F75: =SUM(F45:F74) -> 572 | G75: =SUM(G45:G74) -> 480 | H75: =SUM(H45:H74) -> 372 | I75: =SUM(I45:I74) -> 990 | J75: =SUM(J45:J74) -> 870.5 | K75: =SUM(K45:K74) -> 752 | L75: =SUM(L45:L74) -> 935 | ... AS75: =SUM(AS45:AS74) -> 0
A77: Forecast Revenue by Resource
E78: 2025 | J78: 2026 | V78: 2026 | AH78: 2027
